Workbook

Sheet Resumo
A1: Paris & Disneyland — Outubro 2026
A2: 7 → 11 de outubro · casal · Louvre, Orsay, bouillons, e dois dias de Halloween na Disney.
A4: Período | B4: =Parâmetros!B4 -> 46302 | C4: =Parâmetros!B5 -> 46306
A5: Pessoas · noites · dias | B5: =Parâmetros!B8 -> 2 | C5: =Parâmetros!B6 -> 4 | D5: =Parâmetros!B7 -> 5
A7: Categoria | B7: Tudo econômico | C7: Plano | D7: Escolhido ★ | E7: Tudo upgrade | F7: Real | G7: Real − Escolhido | H7: Intocável
A8: =Parâmetros!B27 -> Voos | B8: =SUMIFS(Itens!$O:$O,Itens!$B:$B,Parâmetros!$A$27) -> 160 | C8: =SUMIFS(Itens!$P:$P,Itens!$B:$B,Parâmetros!$A$27) -> 200 | D8: =SUMIFS(Itens!$R:$R,Itens!$B:$B,Parâmetros!$A$27) -> 200 | E8: =SUMIFS(Itens!$Q:$Q,Itens!$B:$B,Parâmetros!$A$27) -> 328 | F8: =SUMIFS(Real!$G:$G,Real!$B:$B,Parâmetros!$A$27) -> 0 | G8: =IF(F8=0,"",F8-D8) | H8: =Parâmetros!D27 -> não
A9: =Parâmetros!B28 -> Hospedagem | B9: =SUMIFS(Itens!$O:$O,Itens!$B:$B,Parâmetros!$A$28) -> 385 | C9: =SUMIFS(Itens!$P:$P,Itens!$B:$B,Parâmetros!$A$28) -> 510 | D9: =SUMIFS(Itens!$R:$R,Itens!$B:$B,Parâmetros!$A$28) -> 510 | E9: =SUMIFS(Itens!$Q:$Q,Itens!$B:$B,Parâmetros!$A$28) -> 785 | F9: =SUMIFS(Real!$G:$G,Real!$B:$B,Parâmetros!$A$28) -> 0 | G9: =IF(F9=0,"",F9-D9) | H9: =Parâmetros!D28 -> não
A10: =Parâmetros!B29 -> Taxa de turismo | B10: =SUMIFS(Itens!$O:$O,Itens!$B:$B,Parâmetros!$A$29) -> 23 | C10: =SUMIFS(Itens!$P:$P,Itens!$B:$B,Parâmetros!$A$29) -> 23 | D10: =SUMIFS(Itens!$R:$R,Itens!$B:$B,Parâmetros!$A$29) -> 23 | E10: =SUMIFS(Itens!$Q:$Q,Itens!$B:$B,Parâmetros!$A$29) -> 23 | F10: =SUMIFS(Real!$G:$G,Real!$B:$B,Parâmetros!$A$29) -> 0 | G10: =IF(F10=0,"",F10-D10) | H10: =Parâmetros!D29 -> não
A11: =Parâmetros!B30 -> Alimentação | B11: =SUMIFS(Itens!$O:$O,Itens!$B:$B,Parâmetros!$A$30) -> 262.8 | C11: =SUMIFS(Itens!$P:$P,Itens!$B:$B,Parâmetros!$A$30) -> 380 | D11: =SUMIFS(Itens!$R:$R,Itens!$B:$B,Parâmetros!$A$30) -> 380 | E11: =SUMIFS(Itens!$Q:$Q,Itens!$B:$B,Parâmetros!$A$30) -> 606.4 | F11: =SUMIFS(Real!$G:$G,Real!$B:$B,Parâmetros!$A$30) -> 0 | G11: =IF(F11=0,"",F11-D11) | H11: =Parâmetros!D30 -> sim
A12: =Parâmetros!B31 -> Transporte local | B12: =SUMIFS(Itens!$O:$O,Itens!$B:$B,Parâmetros!$A$31) -> 104.281 | C12: =SUMIFS(Itens!$P:$P,Itens!$B:$B,Parâmetros!$A$31) -> 128 | D12: =SUMIFS(Itens!$R:$R,Itens!$B:$B,Parâmetros!$A$31) -> 128 | E12: =SUMIFS(Itens!$Q:$Q,Itens!$B:$B,Parâmetros!$A$31) -> 264 | F12: =SUMIFS(Real!$G:$G,Real!$B:$B,Parâmetros!$A$31) -> 0 | G12: =IF(F12=0,"",F12-D12) | H12: =Parâmetros!D31 -> não
A13: =Parâmetros!B32 -> Atrações | B13: =SUMIFS(Itens!$O:$O,Itens!$B:$B,Parâmetros!$A$32) -> 413.4 | C13: =SUMIFS(Itens!$P:$P,Itens!$B:$B,Parâmetros!$A$32) -> 465 | D13: =SUMIFS(Itens!$R:$R,Itens!$B:$B,Parâmetros!$A$32) -> 465 | E13: =SUMIFS(Itens!$Q:$Q,Itens!$B:$B,Parâmetros!$A$32) -> 691.8 | F13: =SUMIFS(Real!$G:$G,Real!$B:$B,Parâmetros!$A$32) -> 0 | G13: =IF(F13=0,"",F13-D13) | H13: =Parâmetros!D32 -> sim
A14: =Parâmetros!B33 -> Extras e compras | B14: =SUMIFS(Itens!$O:$O,Itens!$B:$B,Parâmetros!$A$33) -> 40 | C14: =SUMIFS(Itens!$P:$P,Itens!$B:$B,Parâmetros!$A$33) -> 80 | D14: =SUMIFS(Itens!$R:$R,Itens!$B:$B,Parâmetros!$A$33) -> 80 | E14: =SUMIFS(Itens!$Q:$Q,Itens!$B:$B,Parâmetros!$A$33) -> 80 | F14: =SUMIFS(Real!$G:$G,Real!$B:$B,Parâmetros!$A$33) -> 0 | G14: =IF(F14=0,"",F14-D14) | H14: =Parâmetros!D33 -> não
A15: Total previsto | B15: =SUM(B8:B14) -> 1388.481 | C15: =SUM(C8:C14) -> 1786 | D15: =SUM(D8:D14) -> 1786 | E15: =SUM(E8:E14) -> 2778.2 | F15: =SUM(F8:F14) -> 0
A16: Reserva para imprevistos | B16: =B15*Parâmetros!$B$13 -> 138.8481 | C16: =C15*Parâmetros!$B$13 -> 178.6 | D16: =D15*Parâmetros!$B$13 -> 178.6 | E16: =E15*Parâmetros!$B$13 -> 277.82
A17: Total com reserva | B17: =B15+B16 -> 1527.3291 | C17: =C15+C16 -> 1964.6 | D17: =D15+D16 -> 1964.6 | E17: =E15+E16 -> 3056.02
A19: Por pessoa | B19: =B15/Parâmetros!$B$8 -> 694.2405 | C19: =C15/Parâmetros!$B$8 -> 893 | D19: =D15/Parâmetros!$B$8 -> 893 | E19: =E15/Parâmetros!$B$8 -> 1389.1 | F19: =F15/Parâmetros!$B$8 -> 0
A20: Por dia (grupo) | B20: =B15/Parâmetros!$B$7 -> 277.6962 | C20: =C15/Parâmetros!$B$7 -> 357.2 | D20: =D15/Parâmetros!$B$7 -> 357.2 | E20: =E15/Parâmetros!$B$7 -> 555.64 | F20: =F15/Parâmetros!$B$7 -> 0
A21: Por pessoa por dia | B21: =B15/Parâmetros!$B$8/Parâmetros!$B$7 -> 138.8481 | C21: =C15/Parâmetros!$B$8/Parâmetros!$B$7 -> 178.6 | D21: =D15/Parâmetros!$B$8/Parâmetros!$B$7 -> 178.6 | E21: =E15/Parâmetros!$B$8/Parâmetros!$B$7 -> 277.82 | F21: =F15/Parâmetros!$B$8/Parâmetros!$B$7 -> 0
A22: Gasto em solo (sem voos) | B22: =B15-SUMIFS(Itens!$O:$O,Itens!$B:$B,"voos") -> 1228.481 | C22: =C15-SUMIFS(Itens!$P:$P,Itens!$B:$B,"voos") -> 1586 | D22: =D15-SUMIFS(Itens!$R:$R,Itens!$B:$B,"voos") -> 1586 | E22: =E15-SUMIFS(Itens!$Q:$Q,Itens!$B:$B,"voos") -> 2450.2
A23: Alimentação / gasto em solo | B23: =IF(B22=0,0,SUMIFS(Itens!$O:$O,Itens!$B:$B,"alimentacao")/B22) -> 0.21392272 | C23: =IF(C22=0,0,SUMIFS(Itens!$P:$P,Itens!$B:$B,"alimentacao")/C22) -> 0.23959647 | D23: =IF(D22=0,0,SUMIFS(Itens!$R:$R,Itens!$B:$B,"alimentacao")/D22) -> 0.23959647 | E23: =IF(E22=0,0,SUMIFS(Itens!$Q:$Q,Itens!$B:$B,"alimentacao")/E22) -> 0.24749 | H23: meta 15–20%
A25: Teto do grupo | B25: =Parâmetros!$B$12 -> 2000 | C25: =Parâmetros!$B$12 -> 2000 | D25: =Parâmetros!$B$12 -> 2000 | E25: =Parâmetros!$B$12 -> 2000
A26: Folga contra o teto | B26: =B25-B17 -> 472.6709 | C26: =C25-C17 -> 35.4 | D26: =D25-D17 -> 35.4 | E26: =E25-E17 -> -1056.02
A27: Uso do teto | B27: =IF(B25=0,0,B17/B25) -> 0.76366455 | C27: =IF(C25=0,0,C17/C25) -> 0.9823 | D27: =IF(D25=0,0,D17/D25) -> 0.9823 | E27: =IF(E25=0,0,E17/E25) -> 1.52801
A28: Veredito | B28: =IF(B26>=0,"cabe, sobram "&TEXT(B26,"#,##0")&" €","faltam "&TEXT(-B26,"#,##0")&" €") -> cabe, sobram 473 € | C28: =IF(C26>=0,"cabe, sobram "&TEXT(C26,"#,##0")&" €","faltam "&TEXT(-C26,"#,##0")&" €") -> cabe, sobram 35 € | D28: =IF(D26>=0,"cabe, sobram "&TEXT(D26,"#,##0")&" €","faltam "&TEXT(-D26,"#,##0")&" €") -> cabe, sobram 35 € | E28: =IF(E26>=0,"cabe, sobram "&TEXT(E26,"#,##0")&" €","faltam "&TEXT(-E26,"#,##0")&" €") -> faltam 1,056 €
A29: Itens em upgrade / econômico | D29: =COUNTIF(Itens!$H:$H,"upgrade")&" up · "&COUNTIF(Itens!$H:$H,"econômico")&" eco" -> 0 up · 0 eco
A31: Como ler
A32: Escolhido ★ é o seu cenário: soma a opção marcada em cada linha da aba Itens (coluna Opção ▼). Tudo econômico e Tudo upgrade são os dois extremos.
A33: Plano = o roteiro como foi pesquisado. Real soma o que você lançar na aba Real durante a viagem; Real − Escolhido mostra onde estourou.
A34: Linhas rosa são intocáveis: a razão de ser da viagem. Cortar ali é planejar outra viagem.
A35: Nada aqui é digitado: tudo vem de Itens, Parâmetros e Real. Para mudar um número, mude lá.

Sheet Parâmetros
A1: Paris & Disneyland — Outubro 2026
A2: Premissas da viagem. Azul = entrada; amarelo = o que mais mexe no total.
A3: Slug | B3: paris-outubro-2026
A4: Início | B4: 46302
A5: Fim | B5: 46306
A6: Noites | B6: =B5-B4 -> 4 | E6: fórmula
A7: Dias de viagem | B7: =B5-B4+1 -> 5 | E7: fórmula
A8: Pessoas | B8: 2
A9: Moeda de casa | B9: EUR
A10: Teto informado | B10: 2000
A11: Teto é por | B11: total | E11: total | pessoa
A12: Teto do grupo | B12: =IF(B11="pessoa",B10*B8,B10) -> 2000 | E12: fórmula
A13: Reserva para imprevistos (%) | B13: 0.1 | E13: sobre o total escolhido
A14: Margem do cartão fora do euro | B14: 0 | E14: 0% num Revolut/Wise; 1–3% em banco tradicional
A15: Opção padrão dos itens | B15: plano | E15: a coluna Opção da aba Itens decide item a item
A16: Pesquisa de | B16: 46277
A17: Status | B17: planejando
A20: Câmbio (EUR por 1 unidade da moeda)
A21: Moeda | B21: EUR por 1 | C21: Data | E21: Fonte
A22: EUR | B22: 1 | C22: 46277 | E22: moeda de casa
A25: Categorias | E25: Fator econômico: preço que sobra na opção econômica quando o item não tem uma explícita (0,8 = corta 20%). Intocável força 1.
A26: ID | B26: Nome | C26: Fator econômico | D26: Intocável | E26: De onde veio o número
A27: voos | B27: Voos | C27: 0.8 | D27: não | E27: Porto ⇄ Orly na Transavia para 2, só bagagem de mão (≈ €100 pp comprando agora; média de outubro €114). Econômico: promoção a €80 pp. Beauvais não entra: o ônibus come a diferença.
A28: hospedagem | B28: Hospedagem | C28: 0.8627 | D28: não | E28: 3 noites no ibis Bastille Opéra (≈ €130) + 1 noite no B&B parceiro da Disney (≈ €120). Econômico: ibis a €110 e B&B a €90.
A29: taxa-turismo | B29: Taxa de turismo | C29: 1 | D29: não | E29: Paris €3,25 pp/noite × 3 + Magny-le-Hongre ≈ €1,50 × 1, para 2.
A30: alimentacao | B30: Alimentação | C30: 1 | D30: sim | E30: €35 pp nos dias de Paris (bouillon, padaria, mercado), €45 pp nos dias de Disney. Comer bem é o motivo — não corta.
A31: transporte-local | B31: Transporte local | C31: 0.8281 | D31: não | E31: Orly €14 × 2 trechos × 2 = €56, RER A Disney €2,55 × 2 × 2 = €10, ≈ 12 bilhetes de metrô × €2,55 × 2 = €62. Econômico: 8 bilhetes de metrô.
A32: atracoes | B32: Atrações | C32: 1 | D32: sim | E32: Disney 2 dias/2 parques ≈ €154 pp (faixa "low", por data), Louvre €22 (residente), Orsay €16, Orangerie €12,50, Sainte-Chapelle €13, Eiffel escada €14,80 — para 2. Econômico: Disney 1 dia/2 parques + 1 dia/1 parque.
A33: extras | B33: Extras e compras | C33: 0.5 | D33: não | E33: Teto assumido — a Disney puxa. Diga o seu.

Sheet Itens
A1: ID | B1: Categoria | C1: Item | D1: Quando | E1: Qtd | F1: Unidade | G1: Moeda | H1: Opção ▼ | I1: Preço econômico | J1: Preço plano | K1: Preço upgrade | L1: Preço escolhido | M1: × (pessoas/noites) | N1: Câmbio + margem | O1: Total econômico (EUR) | P1: Total plano (EUR) | Q1: Total upgrade (EUR) | R1: Total escolhido (EUR) | S1: Intocável | T1: Dia | U1: Reservar / comprar | V1: O que é o econômico | W1: O que é o upgrade | X1: Fonte / observação
A2: voo:ida | B2: voos | C2: Voo OPO → ORY (Transavia) | D2: 46302 | E2: 1 | F2: pessoa | G2: EUR | H2: plano | I2: 40 | J2: 50 | K2: 82 | L2: =IF(H2="econômico",I2,IF(H2="upgrade",K2,J2)) -> 50 | M2: =E2*IF(OR(F2="pessoa",F2="pessoa-noite"),Parâmetros!$B$8,1) -> 2 | N2: =IFERROR(INDEX(Parâmetros!$B$22:$B$22,MATCH(G2,Parâmetros!$A$22:$A$22,0)),1)*(1+IF(G2=Parâmetros!$B$9,0,Parâmetros!$B$14)) -> 1 | O2: =M2*I2*N2 -> 80 | P2: =M2*J2*N2 -> 100 | Q2: =M2*K2*N2 -> 164 | R2: =M2*L2*N2 -> 100 | S2: =IFERROR(INDEX(Parâmetros!$D$27:$D$33,MATCH(B2,Parâmetros!$A$27:$A$33,0)),"não") -> não | U2: transavia.com | V2: Ryanair para Beauvais (≈ €31 o trecho) + ônibus €17,90: mais barato no papel, 1h15 a mais por trecho | W2: TAP para Orly, horário melhor e bagagem despachada (≈ €82 o trecho) | X2: status: cotado
A3: voo:volta | B3: voos | C3: Voo ORY → OPO (Transavia) | D3: 46306 | E3: 1 | F3: pessoa | G3: EUR | H3: plano | I3: 40 | J3: 50 | K3: 82 | L3: =IF(H3="econômico",I3,IF(H3="upgrade",K3,J3)) -> 50 | M3: =E3*IF(OR(F3="pessoa",F3="pessoa-noite"),Parâmetros!$B$8,1) -> 2 | N3: =IFERROR(INDEX(Parâmetros!$B$22:$B$22,MATCH(G3,Parâmetros!$A$22:$A$22,0)),1)*(1+IF(G3=Parâmetros!$B$9,0,Parâmetros!$B$14)) -> 1 | O3: =M3*I3*N3 -> 80 | P3: =M3*J3*N3 -> 100 | Q3: =M3*K3*N3 -> 164 | R3: =M3*L3*N3 -> 100 | S3: =IFERROR(INDEX(Parâmetros!$D$27:$D$33,MATCH(B3,Parâmetros!$A$27:$A$33,0)),"não") -> não | U3: transavia.com | V3: Ryanair para Beauvais (≈ €31 o trecho) + ônibus €17,90: mais barato no papel, 1h15 a mais por trecho | W3: TAP para Orly, horário melhor e bagagem despachada (≈ €82 o trecho) | X3: status: cotado
A4: hosp:hosp-paris | B4: hospedagem | C4: ibis Paris Bastille Opéra 11ème | D4: 46302 | E4: 3 | F4: noite | G4: EUR | H4: plano | I4: 105 | J4: 130 | K4: 175 | L4: =IF(H4="econômico",I4,IF(H4="upgrade",K4,J4)) -> 130 | M4: =E4*IF(OR(F4="pessoa",F4="pessoa-noite"),Parâmetros!$B$8,1) -> 3 | N4: =IFERROR(INDEX(Parâmetros!$B$22:$B$22,MATCH(G4,Parâmetros!$A$22:$A$22,0)),1)*(1+IF(G4=Parâmetros!$B$9,0,Parâmetros!$B$14)) -> 1 | O4: =M4*I4*N4 -> 315 | P4: =M4*J4*N4 -> 390 | Q4: =M4*K4*N4 -> 525 | R4: =M4*L4*N4 -> 390 | S4: =IFERROR(INDEX(Parâmetros!$D$27:$D$33,MATCH(B4,Parâmetros!$A$27:$A$33,0)),"não") -> não | U4: all.accor.com | V4: ibis budget / 2★ no 11º–12º a ≈ €105 a noite (3 noites) | W4: Villa Beaumarchais 4★ no Marais a ≈ €175 a noite (3 noites); €94 "desde" no eDreams, confira o total no checkout | X4: Três noites a ≈ €130 (a quinta é na Disney). Bastille a 7 min, RER A na Gare de Lyon direto para Chessy, Marais a pé, bouillons a dez minutos.
A5: hosp:hosp-disney | B5: hospedagem | C5: B&B Hôtel près de Disneyland Paris (Magny-le-Hongre) | D5: 46303 | E5: 1 | F5: noite | G5: EUR | H5: plano | I5: 70 | J5: 120 | K5: 260 | L5: =IF(H5="econômico",I5,IF(H5="upgrade",K5,J5)) -> 120 | M5: =E5*IF(OR(F5="pessoa",F5="pessoa-noite"),Parâmetros!$B$8,1) -> 1 | N5: =IFERROR(INDEX(Parâmetros!$B$22:$B$22,MATCH(G5,Parâmetros!$A$22:$A$22,0)),1)*(1+IF(G5=Parâmetros!$B$9,0,Parâmetros!$B$14)) -> 1 | O5: =M5*I5*N5 -> 70 | P5: =M5*J5*N5 -> 120 | Q5: =M5*K5*N5 -> 260 | R5: =M5*L5*N5 -> 120 | S5: =IFERROR(INDEX(Parâmetros!$D$27:$D$33,MATCH(B5,Parâmetros!$A$27:$A$33,0)),"não") -> não | U5: hotel-bb.com | V5: B&B Marne-la-Vallée Val d'Europe (Serris), sem ônibus para o parque: RER 1 estação + a pé | W5: Hotel Disney (Santa Fe / Cheyenne) com Extra Magic Time às 8h30 — pacote exige 2 noites desde 31/3/2026 | X5: Parceiro oficial: ônibus grátis a cada 20 min, café incluído, metade do preço de um hotel Disney. O que se perde é a Extra Magic Time das 8h30.
A6: taxa:hosp-paris | B6: taxa-turismo | C6: Taxa de turismo — Paris | D6: 46302 | E6: 3 | F6: pessoa-noite | G6: EUR | H6: plano | I6: =J6*IFERROR(INDEX(Parâmetros!$C$27:$C$33,MATCH(B6,Parâmetros!$A$27:$A$33,0)),1) -> 3.25 | J6: 3.25 | K6: =J6 -> 3.25 | L6: =IF(H6="econômico",I6,IF(H6="upgrade",K6,J6)) -> 3.25 | M6: =E6*IF(OR(F6="pessoa",F6="pessoa-noite"),Parâmetros!$B$8,1) -> 6 | N6: =IFERROR(INDEX(Parâmetros!$B$22:$B$22,MATCH(G6,Parâmetros!$A$22:$A$22,0)),1)*(1+IF(G6=Parâmetros!$B$9,0,Parâmetros!$B$14)) -> 1 | O6: =M6*I6*N6 -> 19.5 | P6: =M6*J6*N6 -> 19.5 | Q6: =M6*K6*N6 -> 19.5 | R6: =M6*L6*N6 -> 19.5 | S6: =IFERROR(INDEX(Parâmetros!$D$27:$D$33,MATCH(B6,Parâmetros!$A$27:$A$33,0)),"não") -> não | V6: — (preço plano × fator da categoria) | W6: — (sem upgrade pesquisado) | X6: cobrada no check-in, por pessoa por noite
A7: taxa:hosp-disney | B7: taxa-turismo | C7: Taxa de turismo — Disneyland Paris | D7: 46303 | E7: 1 | F7: pessoa-noite | G7: EUR | H7: plano | I7: =J7*IFERROR(INDEX(Parâmetros!$C$27:$C$33,MATCH(B7,Parâmetros!$A$27:$A$33,0)),1) -> 1.5 | J7: 1.5 | K7: =J7 -> 1.5 | L7: =IF(H7="econômico",I7,IF(H7="upgrade",K7,J7)) -> 1.5 | M7: =E7*IF(OR(F7="pessoa",F7="pessoa-noite"),Parâmetros!$B$8,1) -> 2 | N7: =IFERROR(INDEX(Parâmetros!$B$22:$B$22,MATCH(G7,Parâmetros!$A$22:$A$22,0)),1)*(1+IF(G7=Parâmetros!$B$9,0,Parâmetros!$B$14)) -> 1 | O7: =M7*I7*N7 -> 3 | P7: =M7*J7*N7 -> 3 | Q7: =M7*K7*N7 -> 3 | R7: =M7*L7*N7 -> 3 | S7: =IFERROR(INDEX(Parâmetros!$D$27:$D$33,MATCH(B7,Parâmetros!$A$27:$A$33,0)),"não") -> não | V7: — (preço plano × fator da categoria) | W7: — (sem upgrade pesquisado) | X7: cobrada no check-in, por pessoa por noite
A8: est:taxa-turismo | B8: taxa-turismo | C8: Estimativa restante — Taxa de turismo | E8: 1 | F8: total | G8: EUR | H8: plano | I8: =J8*IFERROR(INDEX(Parâmetros!$C$27:$C$33,MATCH(B8,Parâmetros!$A$27:$A$33,0)),1) -> 0.5 | J8: 0.5 | K8: =J8 -> 0.5 | L8: =IF(H8="econômico",I8,IF(H8="upgrade",K8,J8)) -> 0.5 | M8: =E8*IF(OR(F8="pessoa",F8="pessoa-noite"),Parâmetros!$B$8,1) -> 1 | N8: =IFERROR(INDEX(Parâmetros!$B$22:$B$22,MATCH(G8,Parâmetros!$A$22:$A$22,0)),1)*(1+IF(G8=Parâmetros!$B$9,0,Parâmetros!$B$14)) -> 1 | O8: =M8*I8*N8 -> 0.5 | P8: =M8*J8*N8 -> 0.5 | Q8: =M8*K8*N8 -> 0.5 | R8: =M8*L8*N8 -> 0.5 | S8: =IFERROR(INDEX(Parâmetros!$D$27:$D$33,MATCH(B8,Parâmetros!$A$27:$A$33,0)),"não") -> não | X8: Paris €3,25 pp/noite × 3 + Magny-le-Hongre ≈ €1,50 × 1, para 2.
A9: dia1:p2 | B9: alimentacao | C9: Almoço de padaria no Marais: fórmula sanduíche + doce | D9: 46302 | E9: 1 | F9: pessoa | G9: EUR | H9: plano | I9: 5.4 | J9: 9 | K9: 16.2 | L9: =IF(H9="econômico",I9,IF(H9="upgrade",K9,J9)) -> 9 | M9: =E9*IF(OR(F9="pessoa",F9="pessoa-noite"),Parâmetros!$B$8,1) -> 2 | N9: =IFERROR(INDEX(Parâmetros!$B$22:$B$22,MATCH(G9,Parâmetros!$A$22:$A$22,0)),1)*(1+IF(G9=Parâmetros!$B$9,0,Parâmetros!$B$14)) -> 1 | O9: =M9*I9*N9 -> 10.8 | P9: =M9*J9*N9 -> 18 | Q9: =M9*K9*N9 -> 32.4 | R9: =M9*L9*N9 -> 18 | S9: =IFERROR(INDEX(Parâmetros!$D$27:$D$33,MATCH(B9,Parâmetros!$A$27:$A$33,0)),"não") -> sim | T9: 1 | V9: padaria / mercado | W9: restaurante com reserva e vinho
A10: dia1:p6 | B10: alimentacao | C10: Bouillon Chartier: menu completo por menos de €20 | D10: 46302 | E10: 1 | F10: pessoa | G10: EUR | H10: plano | I10: 9 | J10: 19 | K10: 35 | L10: =IF(H10="econômico",I10,IF(H10="upgrade",K10,J10)) -> 19 | M10: =E10*IF(OR(F10="pessoa",F10="pessoa-noite"),Parâmetros!$B$8,1) -> 2 | N10: =IFERROR(INDEX(Parâmetros!$B$22:$B$22,MATCH(G10,Parâmetros!$A$22:$A$22,0)),1)*(1+IF(G10=Parâmetros!$B$9,0,Parâmetros!$B$14)) -> 1 | O10: =M10*I10*N10 -> 18 | P10: =M10*J10*N10 -> 38 | Q10: =M10*K10*N10 -> 70 | R10: =M10*L10*N10 -> 38 | S10: =IFERROR(INDEX(Parâmetros!$D$27:$D$33,MATCH(B10,Parâmetros!$A$27:$A$33,0)),"não") -> sim | T10: 1 | U10: bouillon-chartier.com | V10: fórmula de padaria | W10: bistrô no Marais com vinho | X10: Sem reserva, fila anda rápido. Sopa de cebola, steak-frites, crème caramel.
A11: dia2:d3 | B11: alimentacao | C11: Almoço no parque | D11: 46303 | E11: 1 | F11: pessoa | G11: EUR | H11: plano | I11: 15 | J11: 25 | K11: 45 | L11: =IF(H11="econômico",I11,IF(H11="upgrade",K11,J11)) -> 25 | M11: =E11*IF(OR(F11="pessoa",F11="pessoa-noite"),Parâmetros!$B$8,1) -> 2 | N11: =IFERROR(INDEX(Parâmetros!$B$22:$B$22,MATCH(G11,Parâmetros!$A$22:$A$22,0)),1)*(1+IF(G11=Parâmetros!$B$9,0,Parâmetros!$B$14)) -> 1 | O11: =M11*I11*N11 -> 30 | P11: =M11*J11*N11 -> 50 | Q11: =M11*K11*N11 -> 90 | R11: =M11*L11*N11 -> 50 | S11: =IFERROR(INDEX(Parâmetros!$D$27:$D$33,MATCH(B11,Parâmetros!$A$27:$A$33,0)),"não") -> sim | T11: 2 | V11: padaria / mercado | W11: restaurante com reserva e vinho
A12: dia3:d10 | B12: alimentacao | C12: Jantar leve perto do hotel | D12: 46304 | E12: 1 | F12: pessoa | G12: EUR | H12: plano | I12: 10.8 | J12: 18 | K12: 32.4 | L12: =IF(H12="econômico",I12,IF(H12="upgrade",K12,J12)) -> 18 | M12: =E12*IF(OR(F12="pessoa",F12="pessoa-noite"),Parâmetros!$B$8,1) -> 2 | N12: =IFERROR(INDEX(Parâmetros!$B$22:$B$22,MATCH(G12,Parâmetros!$A$22:$A$22,0)),1)*(1+IF(G12=Parâmetros!$B$9,0,Parâmetros!$B$14)) -> 1 | O12: =M12*I12*N12 -> 21.6 | P12: =M12*J12*N12 -> 36 | Q12: =M12*K12*N12 -> 64.8 | R12: =M12*L12*N12 -> 36 | S12: =IFERROR(INDEX(Parâmetros!$D$27:$D$33,MATCH(B12,Parâmetros!$A$27:$A$33,0)),"não") -> sim | T12: 3 | V12: padaria / mercado | W12: restaurante com reserva e vinho
A13: dia3:d7 | B13: alimentacao | C13: Almoço no parque | D13: 46304 | E13: 1 | F13: pessoa | G13: EUR | H13: plano | I13: 15 | J13: 25 | K13: 45 | L13: =IF(H13="econômico",I13,IF(H13="upgrade",K13,J13)) -> 25 | M13: =E13*IF(OR(F13="pessoa",F13="pessoa-noite"),Parâmetros!$B$8,1) -> 2 | N13: =IFERROR(INDEX(Parâmetros!$B$22:$B$22,MATCH(G13,Parâmetros!$A$22:$A$22,0)),1)*(1+IF(G13=Parâmetros!$B$9,0,Parâmetros!$B$14)) -> 1 | O13: =M13*I13*N13 -> 30 | P13: =M13*J13*N13 -> 50 | Q13: =M13*K13*N13 -> 90 | R13: =M13*L13*N13 -> 50 | S13: =IFERROR(INDEX(Parâmetros!$D$27:$D$33,MATCH(B13,Parâmetros!$A$27:$A$33,0)),"não") -> sim | T13: 3 | V13: padaria / mercado | W13: restaurante com reserva e vinho
A14: dia4:p12 | B14: alimentacao | C14: Jantar em bistrô do 7e ou Bouillon Pigalle | D14: 46305 | E14: 1 | F14: pessoa | G14: EUR | H14: plano | I14: 13.2 | J14: 22 | K14: 39.6 | L14: =IF(H14="econômico",I14,IF(H14="upgrade",K14,J14)) -> 22 | M14: =E14*IF(OR(F14="pessoa",F14="pessoa-noite"),Parâmetros!$B$8,1) -> 2 | N14: =IFERROR(INDEX(Parâmetros!$B$22:$B$22,MATCH(G14,Parâmetros!$A$22:$A$22,0)),1)*(1+IF(G14=Parâmetros!$B$9,0,Parâmetros!$B$14)) -> 1 | O14: =M14*I14*N14 -> 26.4 | P14: =M14*J14*N14 -> 44 | Q14: =M14*K14*N14 -> 79.2 | R14: =M14*L14*N14 -> 44 | S14: =IFERROR(INDEX(Parâmetros!$D$27:$D$33,MATCH(B14,Parâmetros!$A$27:$A$33,0)),"não") -> sim | T14: 4 | V14: padaria / mercado | W14: restaurante com reserva e vinho
A15: dia4:p8 | B15: alimentacao | C15: Piquenique nas Tulherias ou padaria da Rue de Rivoli | D15: 46305 | E15: 1 | F15: pessoa | G15: EUR | H15: plano | I15: 6 | J15: 10 | K15: 18 | L15: =IF(H15="econômico",I15,IF(H15="upgrade",K15,J15)) -> 10 | M15: =E15*IF(OR(F15="pessoa",F15="pessoa-noite"),Parâmetros!$B$8,1) -> 2 | N15: =IFERROR(INDEX(Parâmetros!$B$22:$B$22,MATCH(G15,Parâmetros!$A$22:$A$22,0)),1)*(1+IF(G15=Parâmetros!$B$9,0,Parâmetros!$B$14)) -> 1 | O15: =M15*I15*N15 -> 12 | P15: =M15*J15*N15 -> 20 | Q15: =M15*K15*N15 -> 36 | R15: =M15*L15*N15 -> 20 | S15: =IFERROR(INDEX(Parâmetros!$D$27:$D$33,MATCH(B15,Parâmetros!$A$27:$A$33,0)),"não") -> sim | T15: 4 | V15: padaria / mercado | W15: restaurante com reserva e vinho
A16: dia5:p14 | B16: alimentacao | C16: Marché d'Aligre: queijo, ostras e um copo no balcão | D16: 46306 | E16: 1 | F16: pessoa | G16: EUR | H16: plano | I16: 10 | J16: 15 | K16: 25 | L16: =IF(H16="econômico",I16,IF(H16="upgrade",K16,J16)) -> 15 | M16: =E16*IF(OR(F16="pessoa",F16="pessoa-noite"),Parâmetros!$B$8,1) -> 2 | N16: =IFERROR(INDEX(Parâmetros!$B$22:$B$22,MATCH(G16,Parâmetros!$A$22:$A$22,0)),1)*(1+IF(G16=Parâmetros!$B$9,0,Parâmetros!$B$14)) -> 1 | O16: =M16*I16*N16 -> 20 | P16: =M16*J16*N16 -> 30 | Q16: =M16*K16*N16 -> 50 | R16: =M16*L16*N16 -> 30 | S16: =IFERROR(INDEX(Parâmetros!$D$27:$D$33,MATCH(B16,Parâmetros!$A$27:$A$33,0)),"não") -> sim | T16: 5 | U16: marchedaligre.fr | V16: sanduíche de padaria | W16: ostras e vinho no mercado | X16: O mercado mais barato de Paris, e é domingo de manhã que ele está inteiro. Fecha às 13h30.
A17: est:alimentacao | B17: alimentacao | C17: Estimativa restante — Alimentação | E17: 1 | F17: total | G17: EUR | H17: plano | I17: =J17*IFERROR(INDEX(Parâmetros!$C$27:$C$33,MATCH(B17,Parâmetros!$A$27:$A$33,0)),1) -> 94 | J17: 94 | K17: =J17 -> 94 | L17: =IF(H17="econômico",I17,IF(H17="upgrade",K17,J17)) -> 94 | M17: =E17*IF(OR(F17="pessoa",F17="pessoa-noite"),Parâmetros!$B$8,1) -> 1 | N17: =IFERROR(INDEX(Parâmetros!$B$22:$B$22,MATCH(G17,Parâmetros!$A$22:$A$22,0)),1)*(1+IF(G17=Parâmetros!$B$9,0,Parâmetros!$B$14)) -> 1 | O17: =M17*I17*N17 -> 94 | P17: =M17*J17*N17 -> 94 | Q17: =M17*K17*N17 -> 94 | R17: =M17*L17*N17 -> 94 | S17: =IFERROR(INDEX(Parâmetros!$D$27:$D$33,MATCH(B17,Parâmetros!$A$27:$A$33,0)),"não") -> sim | X17: €35 pp nos dias de Paris (bouillon, padaria, mercado), €45 pp nos dias de Disney. Comer bem é o motivo — não corta.
A18: transp:metro | B18: transporte-local | C18: Bilhetes de metrô, ≈ 12 viagens | E18: 1 | F18: pessoa | G18: EUR | H18: plano | I18: 20 | J18: 31 | K18: 37 | L18: =IF(H18="econômico",I18,IF(H18="upgrade",K18,J18)) -> 31 | M18: =E18*IF(OR(F18="pessoa",F18="pessoa-noite"),Parâmetros!$B$8,1) -> 2 | N18: =IFERROR(INDEX(Parâmetros!$B$22:$B$22,MATCH(G18,Parâmetros!$A$22:$A$22,0)),1)*(1+IF(G18=Parâmetros!$B$9,0,Parâmetros!$B$14)) -> 1 | O18: =M18*I18*N18 -> 40 | P18: =M18*J18*N18 -> 62 | Q18: =M18*K18*N18 -> 74 | R18: =M18*L18*N18 -> 62 | S18: =IFERROR(INDEX(Parâmetros!$D$27:$D$33,MATCH(B18,Parâmetros!$A$27:$A$33,0)),"não") -> não | U18: bonjour-ratp.fr | V18: andar mais e usar 8 bilhetes em vez de 12 | W18: Navigo Jour €12,30 nos 3 dias de Paris (só compensa com 5+ viagens no dia) | X18: Navigo Semaine só vale de segunda a domingo — não serve para quarta a domingo. Passe de dia (€12,30) só compensa com 5+ viagens.
A19: transp:orly | B19: transporte-local | C19: Orly ⇄ Paris pelo metrô 14 (bilhete aeroporto €14) | E19: 1 | F19: pessoa | G19: EUR | H19: plano | I19: 28 | J19: 28 | K19: 90 | L19: =IF(H19="econômico",I19,IF(H19="upgrade",K19,J19)) -> 28 | M19: =E19*IF(OR(F19="pessoa",F19="pessoa-noite"),Parâmetros!$B$8,1) -> 2 | N19: =IFERROR(INDEX(Parâmetros!$B$22:$B$22,MATCH(G19,Parâmetros!$A$22:$A$22,0)),1)*(1+IF(G19=Parâmetros!$B$9,0,Parâmetros!$B$14)) -> 1 | O19: =M19*I19*N19 -> 56 | P19: =M19*J19*N19 -> 56 | Q19: =M19*K19*N19 -> 180 | R19: =M19*L19*N19 -> 56 | S19: =IFERROR(INDEX(Parâmetros!$D$27:$D$33,MATCH(B19,Parâmetros!$A$27:$A$33,0)),"não") -> não | U19: bonjour-ratp.fr | V19: — | W19: táxi tarifa fixa Orly ⇄ margem direita €44 por trecho, dividido por 2 | X19: 25 min até Châtelet. O bilhete de €2,55 não vale para aeroporto.
A20: transp:rer-disney | B20: transporte-local | C20: RER A Paris ⇄ Marne-la-Vallée–Chessy | E20: 1 | F20: pessoa | G20: EUR | H20: plano | I20: =J20*IFERROR(INDEX(Parâmetros!$C$27:$C$33,MATCH(B20,Parâmetros!$A$27:$A$33,0)),1) -> 4.1405 | J20: 5 | K20: =J20 -> 5 | L20: =IF(H20="econômico",I20,IF(H20="upgrade",K20,J20)) -> 5 | M20: =E20*IF(OR(F20="pessoa",F20="pessoa-noite"),Parâmetros!$B$8,1) -> 2 | N20: =IFERROR(INDEX(Parâmetros!$B$22:$B$22,MATCH(G20,Parâmetros!$A$22:$A$22,0)),1)*(1+IF(G20=Parâmetros!$B$9,0,Parâmetros!$B$14)) -> 1 | O20: =M20*I20*N20 -> 8.281 | P20: =M20*J20*N20 -> 10 | Q20: =M20*K20*N20 -> 10 | R20: =M20*L20*N20 -> 10 | S20: =IFERROR(INDEX(Parâmetros!$D$27:$D$33,MATCH(B20,Parâmetros!$A$27:$A$33,0)),"não") -> não | U20: bonjour-ratp.fr | V20: — (preço plano × fator da categoria) | W20: — (sem upgrade pesquisado) | X20: Bilhete único de €2,55 vale até a Disney desde 2025. 40 min de Nation; a estação sai na porta do parque.
A21: dia1:p3 | B21: atracoes | C21: Sainte-Chapelle — com hora marcada | D21: 46302 | E21: 1 | F21: pessoa | G21: EUR | H21: plano | I21: 10 | J21: 13 | K21: 20 | L21: =IF(H21="econômico",I21,IF(H21="upgrade",K21,J21)) -> 13 | M21: =E21*IF(OR(F21="pessoa",F21="pessoa-noite"),Parâmetros!$B$8,1) -> 2 | N21: =IFERROR(INDEX(Parâmetros!$B$22:$B$22,MATCH(G21,Parâmetros!$A$22:$A$22,0)),1)*(1+IF(G21=Parâmetros!$B$9,0,Parâmetros!$B$14)) -> 1 | O21: =M21*I21*N21 -> 20 | P21: =M21*J21*N21 -> 26 | Q21: =M21*K21*N21 -> 40 | R21: =M21*L21*N21 -> 26 | S21: =IFERROR(INDEX(Parâmetros!$D$27:$D$33,MATCH(B21,Parâmetros!$A$27:$A$33,0)),"não") -> sim | T21: 1 | U21: sainte-chapelle.fr | V21: só o exterior + Notre-Dame (grátis) | W21: bilhete combinado Sainte-Chapelle + Conciergerie | X21: Os vitrais pedem sol: se a tarde estiver cinza, troque pela manhã de domingo.
A22: dia2:d2 | B22: atracoes | C22: Disneyland Park — abertura às 9h30 | D22: 46303 | E22: 1 | F22: pessoa | G22: EUR | H22: plano | I22: 142 | J22: 150 | K22: 200 | L22: =IF(H22="econômico",I22,IF(H22="upgrade",K22,J22)) -> 150 | M22: =E22*IF(OR(F22="pessoa",F22="pessoa-noite"),Parâmetros!$B$8,1) -> 2 | N22: =IFERROR(INDEX(Parâmetros!$B$22:$B$22,MATCH(G22,Parâmetros!$A$22:$A$22,0)),1)*(1+IF(G22=Parâmetros!$B$9,0,Parâmetros!$B$14)) -> 1 | O22: =M22*I22*N22 -> 284 | P22: =M22*J22*N22 -> 300 | Q22: =M22*K22*N22 -> 400 | R22: =M22*L22*N22 -> 300 | S22: =IFERROR(INDEX(Parâmetros!$D$27:$D$33,MATCH(B22,Parâmetros!$A$27:$A$33,0)),"não") -> sim | T22: 2 | U22: disneylandparis.com | V22: faixa "eco" — trocar para 30/9–1/10 se o preço por data for menor | W22: + Disney Premier Access One (3 atrações) ≈ €45 pp | X22: Ingresso de 2 dias, com data. Big Thunder Mountain e Phantom Manor primeiro; Halloween é no Frontierland.
A23: dia4:p11 | B23: atracoes | C23: Torre Eiffel pela escada, até o 2º andar | D23: 46305 | E23: 1 | F23: pessoa | G23: EUR | H23: plano | I23: 0 | J23: 14.8 | K23: 36.7 | L23: =IF(H23="econômico",I23,IF(H23="upgrade",K23,J23)) -> 14.8 | M23: =E23*IF(OR(F23="pessoa",F23="pessoa-noite"),Parâmetros!$B$8,1) -> 2 | N23: =IFERROR(INDEX(Parâmetros!$B$22:$B$22,MATCH(G23,Parâmetros!$A$22:$A$22,0)),1)*(1+IF(G23=Parâmetros!$B$9,0,Parâmetros!$B$14)) -> 1 | O23: =M23*I23*N23 -> 0 | P23: =M23*J23*N23 -> 29.6 | Q23: =M23*K23*N23 -> 73.4 | R23: =M23*L23*N23 -> 29.6 | S23: =IFERROR(INDEX(Parâmetros!$D$27:$D$33,MATCH(B23,Parâmetros!$A$27:$A$33,0)),"não") -> sim | T23: 4 | U23: toureiffel.paris | V23: ver de baixo, do Trocadéro, na hora da cintilação | W23: elevador até o topo | X23: 674 degraus, 20 minutos. Pôr do sol ≈ 19h15. Depois de escurecer a torre cintila 5 minutos a cada hora cheia — do Trocadéro é a melhor vista
A24: dia4:p7 | B24: atracoes | C24: Louvre — entrada 9h, tarifa residente EEE | D24: 46305 | E24: 1 | F24: pessoa | G24: EUR | H24: plano | I24: 22 | J24: 22 | K24: 45 | L24: =IF(H24="econômico",I24,IF(H24="upgrade",K24,J24)) -> 22 | M24: =E24*IF(OR(F24="pessoa",F24="pessoa-noite"),Parâmetros!$B$8,1) -> 2 | N24: =IFERROR(INDEX(Parâmetros!$B$22:$B$22,MATCH(G24,Parâmetros!$A$22:$A$22,0)),1)*(1+IF(G24=Parâmetros!$B$9,0,Parâmetros!$B$14)) -> 1 | O24: =M24*I24*N24 -> 44 | P24: =M24*J24*N24 -> 44 | Q24: =M24*K24*N24 -> 90 | R24: =M24*L24*N24 -> 44 | S24: =IFERROR(INDEX(Parâmetros!$D$27:$D$33,MATCH(B24,Parâmetros!$A$27:$A$33,0)),"não") -> sim | T24: 4 | U24: louvre.fr | V24: primeira sexta do mês 18h–21h é grátis (não cai na viagem) | W24: visita guiada oficial 1h30 | X24: Entre pela Porte des Lions se estiver aberta: fila menor. Ala Denon primeiro (Vitória de Samotrácia, Gioconda), depois Sully.
A25: dia4:p9 | B25: atracoes | C25: Orangerie: as Ninfeias de Monet | D25: 46305 | E25: 1 | F25: pessoa | G25: EUR | H25: plano | I25: 12.5 | J25: 12.5 | K25: 18 | L25: =IF(H25="econômico",I25,IF(H25="upgrade",K25,J25)) -> 12.5 | M25: =E25*IF(OR(F25="pessoa",F25="pessoa-noite"),Parâmetros!$B$8,1) -> 2 | N25: =IFERROR(INDEX(Parâmetros!$B$22:$B$22,MATCH(G25,Parâmetros!$A$22:$A$22,0)),1)*(1+IF(G25=Parâmetros!$B$9,0,Parâmetros!$B$14)) -> 1 | O25: =M25*I25*N25 -> 25 | P25: =M25*J25*N25 -> 25 | Q25: =M25*K25*N25 -> 36 | R25: =M25*L25*N25 -> 25 | S25: =IFERROR(INDEX(Parâmetros!$D$27:$D$33,MATCH(B25,Parâmetros!$A$27:$A$33,0)),"não") -> sim | T25: 4 | U25: musee-orangerie.fr | V25: — | W25: bilhete combinado Orsay + Orangerie | X25: Pequeno; uma hora e meia sobra. Fecha terça, como o Louvre.
A26: dia5:p13 | B26: atracoes | C26: Musée d'Orsay — entrada 9h30 | D26: 46306 | E26: 1 | F26: pessoa | G26: EUR | H26: plano | I26: 16 | J26: 16 | K26: 22 | L26: =IF(H26="econômico",I26,IF(H26="upgrade",K26,J26)) -> 16 | M26: =E26*IF(OR(F26="pessoa",F26="pessoa-noite"),Parâmetros!$B$8,1) -> 2 | N26: =IFERROR(INDEX(Parâmetros!$B$22:$B$22,MATCH(G26,Parâmetros!$A$22:$A$22,0)),1)*(1+IF(G26=Parâmetros!$B$9,0,Parâmetros!$B$14)) -> 1 | O26: =M26*I26*N26 -> 32 | P26: =M26*J26*N26 -> 32 | Q26: =M26*K26*N26 -> 44 | R26: =M26*L26*N26 -> 32 | S26: =IFERROR(INDEX(Parâmetros!$D$27:$D$33,MATCH(B26,Parâmetros!$A$27:$A$33,0)),"não") -> sim | T26: 5 | U26: musee-orsay.fr | V26: primeiro domingo do mês grátis (só na janela 30/9–4/10) | W26: bilhete combinado Orsay + Orangerie | X26: Impressionistas no 5º andar; suba direto e desça depois. O relógio da fachada dá a foto.
A27: est:atracoes | B27: atracoes | C27: Estimativa restante — Atrações | E27: 1 | F27: total | G27: EUR | H27: plano | I27: =J27*IFERROR(INDEX(Parâmetros!$C$27:$C$33,MATCH(B27,Parâmetros!$A$27:$A$33,0)),1) -> 8.4 | J27: 8.4 | K27: =J27 -> 8.4 | L27: =IF(H27="econômico",I27,IF(H27="upgrade",K27,J27)) -> 8.4 | M27: =E27*IF(OR(F27="pessoa",F27="pessoa-noite"),Parâmetros!$B$8,1) -> 1 | N27: =IFERROR(INDEX(Parâmetros!$B$22:$B$22,MATCH(G27,Parâmetros!$A$22:$A$22,0)),1)*(1+IF(G27=Parâmetros!$B$9,0,Parâmetros!$B$14)) -> 1 | O27: =M27*I27*N27 -> 8.4 | P27: =M27*J27*N27 -> 8.4 | Q27: =M27*K27*N27 -> 8.4 | R27: =M27*L27*N27 -> 8.4 | S27: =IFERROR(INDEX(Parâmetros!$D$27:$D$33,MATCH(B27,Parâmetros!$A$27:$A$33,0)),"não") -> sim | X27: Disney 2 dias/2 parques ≈ €154 pp (faixa "low", por data), Louvre €22 (residente), Orsay €16, Orangerie €12,50, Sainte-Chapelle €13, Eiffel escada €14,80 — para 2. Econômico: Disney 1 dia/2 parques + 1 dia/1 parque.
A28: est:extras | B28: extras | C28: Estimativa restante — Extras e compras | E28: 1 | F28: total | G28: EUR | H28: plano | I28: =J28*IFERROR(INDEX(Parâmetros!$C$27:$C$33,MATCH(B28,Parâmetros!$A$27:$A$33,0)),1) -> 40 | J28: 80 | K28: =J28 -> 80 | L28: =IF(H28="econômico",I28,IF(H28="upgrade",K28,J28)) -> 80 | M28: =E28*IF(OR(F28="pessoa",F28="pessoa-noite"),Parâmetros!$B$8,1) -> 1 | N28: =IFERROR(INDEX(Parâmetros!$B$22:$B$22,MATCH(G28,Parâmetros!$A$22:$A$22,0)),1)*(1+IF(G28=Parâmetros!$B$9,0,Parâmetros!$B$14)) -> 1 | O28: =M28*I28*N28 -> 40 | P28: =M28*J28*N28 -> 80 | Q28: =M28*K28*N28 -> 80 | R28: =M28*L28*N28 -> 80 | S28: =IFERROR(INDEX(Parâmetros!$D$27:$D$33,MATCH(B28,Parâmetros!$A$27:$A$33,0)),"não") -> não | X28: Teto assumido — a Disney puxa. Diga o seu.
C30: Como usar
C31: Opção ▼ (coluna H, fundo creme) escolhe o que entra no total: econômico, plano ou upgrade. É o único lugar que você precisa mexer para montar o seu cenário.
C32: As três colunas de preço são por unidade (por pessoa, por noite ou total, conforme a Unidade). Azul = pesquisado; preto = derivado do plano.
C33: Preço econômico sem número explícito = preço do plano × fator da categoria (aba Parâmetros). Preço upgrade sem número = igual ao plano.
C34: Reservar / comprar (coluna U) abre o site oficial ou o comparador. Compre pelo link; a taxa de serviço de agregador entra no último passo.
C35: Linhas em itálico são estimativas da categoria: ao detalhar um item novo, reduza a estimativa para não contar duas vezes.
C36: Para acrescentar um item: copie uma linha inteira (as fórmulas de L a S vêm junto) e troque ID, categoria, preços e link.

Sheet Roteiro
A1: Roteiro dia a dia
A2: Custo de cada bloco vem da aba Itens (opção escolhida). Marque Feito durante a viagem.
A4: Dia | B4: Data | C4: Semana | D4: Hora | E4: Bloco | F4: Tipo | G4: Custo escolhido (EUR) | H4: Opção | I4: Reservar antes | J4: Feito | K4: Link | L4: Notas / plano B
A5: 1 | B5: 46302 | C5: quarta | E5: Chegada e a Île de la Cité | L5: Meio dia. Nada com hora antes das 15h; a ilha e o Marais a pé, e o primeiro bouillon.
D6: 10:40 | E6: Orly → Châtelet pelo metrô 14 | F6: deslocamento | K6: bonjour-ratp.fr
D7: 12:30 | E7: Almoço de padaria no Marais: fórmula sanduíche + doce | F7: refeicao | G7: =Itens!R9 -> 18 | H7: =Itens!H9 -> plano
D8: 15:00 | E8: Sainte-Chapelle — com hora marcada | F8: atracao | G8: =Itens!R21 -> 26 | H8: =Itens!H21 -> plano | I8: sim | K8: sainte-chapelle.fr | L8: Os vitrais pedem sol: se a tarde estiver cinza, troque pela manhã de domingo.
D9: 16:30 | E9: Notre-Dame por dentro (grátis) e a Île Saint-Louis | F9: atracao | L9: Fila sem reserva anda em 20 min fora do fim de semana.
D10: 18:00 | E10: Place des Vosges e o Marais ao anoitecer | F10: livre
D11: 19:30 | E11: Bouillon Chartier: menu completo por menos de €20 | F11: refeicao | G11: =Itens!R10 -> 38 | H11: =Itens!H10 -> plano | K11: bouillon-chartier.com | L11: Sem reserva, fila anda rápido. Sopa de cebola, steak-frites, crème caramel.
E12: Custo do dia 1 | G12: =SUM(G6:G11) -> 82
A14: 2 | B14: 46303 | C14: quinta | E14: Disney, dia 1 | L14: Quinta-feira, antes da Toussaint: o parque abre às 9h30 e fecha às 22h, com o Halloween Festival incluído. Chegue na abertura e abra a fila virtual das atrações grandes no app assim que entrar.
D15: 08:00 | E15: RER A Nation → Marne-la-Vallée–Chessy | F15: deslocamento | L15: Bilhete de €2,55 no app ou na máquina. Sente na frente do trem: a saída em Chessy é do lado do parque.
D16: 09:30 | E16: Disneyland Park — abertura às 9h30 | F16: atracao | G16: =Itens!R22 -> 300 | H16: =Itens!H22 -> plano | I16: sim | K16: disneylandparis.com | L16: Ingresso de 2 dias, com data. Big Thunder Mountain e Phantom Manor primeiro; Halloween é no Frontierland.
D17: 13:00 | E17: Almoço no parque | F17: refeicao | G17: =Itens!R11 -> 50 | H17: =Itens!H11 -> plano
D18: 17:00 | E18: Check-in no B&B parceiro (ônibus grátis) e um banho | F18: deslocamento
D19: 19:00 | E19: Volta ao parque: desfile e show de Halloween | F19: evento | L19: Os shows noturnos são o motivo de dormir aqui. Jantar leve no parque.
E20: Custo do dia 2 | G20: =SUM(G15:G19) -> 350
A22: 3 | B22: 46304 | C22: sexta | E22: Disney, dia 2 | L22: O segundo parque é menor: meio dia basta. Volte ao primeiro para o que ficou de fora, e pegue o RER antes do jantar.
D23: 09:30 | E23: Walt Disney Studios Park | F23: atracao | K23: disneylandparis.com | L23: Aberto até 20h. Ratatouille e Avengers Campus na primeira hora.
D24: 13:00 | E24: Almoço no parque | F24: refeicao | G24: =Itens!R13 -> 50 | H24: =Itens!H13 -> plano
D25: 16:00 | E25: Disneyland Park de novo: o que faltou, e a Main Street ao entardecer | F25: atracao | K25: disneylandparis.com
D26: 19:00 | E26: RER A Chessy → Nation | F26: deslocamento
D27: 20:30 | E27: Jantar leve perto do hotel | F27: refeicao | G27: =Itens!R12 -> 36 | H27: =Itens!H12 -> plano
E28: Custo do dia 3 | G28: =SUM(G23:G27) -> 86
A30: 4 | B30: 46305 | C30: sábado | E30: Louvre e a torre cintilando | L30: Sábado é dia de Louvre porque terça ele fecha. Três horas com hora marcada, o Jardim das Tulherias no meio, e a torre no fim do dia.
D31: 09:00 | E31: Louvre — entrada 9h, tarifa residente EEE | F31: atracao | G31: =Itens!R24 -> 44 | H31: =Itens!H24 -> plano | I31: sim | K31: louvre.fr | L31: Entre pela Porte des Lions se estiver aberta: fila menor. Ala Denon primeiro (Vitória de Samotrácia, Gioconda), depois Sully. · Plano B: Chovendo, o Louvre é o melhor lugar de Paris — o plano B é ficar mais.
D32: 12:30 | E32: Piquenique nas Tulherias ou padaria da Rue de Rivoli | F32: refeicao | G32: =Itens!R15 -> 20 | H32: =Itens!H15 -> plano
D33: 15:00 | E33: Orangerie: as Ninfeias de Monet | F33: atracao | G33: =Itens!R25 -> 25 | H33: =Itens!H25 -> plano | I33: sim | K33: musee-orangerie.fr | L33: Pequeno; uma hora e meia sobra. Fecha terça, como o Louvre.
D34: 17:00 | E34: Champ de Mars e o Trocadéro ao entardecer | F34: livre
D35: 19:00 | E35: Torre Eiffel pela escada, até o 2º andar | F35: atracao | G35: =Itens!R23 -> 29.6 | H35: =Itens!H23 -> plano | I35: sim | K35: toureiffel.paris | L35: 674 degraus, 20 minutos. Pôr do sol ≈ 19h15. Depois de escurecer a torre cintila 5 minutos a cada hora cheia — do Trocadéro é a melhor vista. · Plano B: Sem ingresso, o Trocadéro às 20h e às 21h dá a cintilação de graça.
D36: 21:00 | E36: Jantar em bistrô do 7e ou Bouillon Pigalle | F36: refeicao | G36: =Itens!R14 -> 44 | H36: =Itens!H14 -> plano
E37: Custo do dia 4 | G37: =SUM(G31:G36) -> 162.6
A39: 5 | B39: 46306 | C39: domingo | E39: Orsay, mercado e volta | L39: Domingo é Orsay porque segunda ele fecha. Mercado de domingo na Aligre, uma volta no Luxembourg, e Orly com folga.
D40: 09:30 | E40: Musée d'Orsay — entrada 9h30 | F40: atracao | G40: =Itens!R26 -> 32 | H40: =Itens!H26 -> plano | I40: sim | K40: musee-orsay.fr | L40: Impressionistas no 5º andar; suba direto e desça depois. O relógio da fachada dá a foto.
D41: 12:30 | E41: Marché d'Aligre: queijo, ostras e um copo no balcão | F41: refeicao | G41: =Itens!R16 -> 30 | H41: =Itens!H16 -> plano | K41: marchedaligre.fr | L41: O mercado mais barato de Paris, e é domingo de manhã que ele está inteiro. Fecha às 13h30.
D42: 14:30 | E42: Jardin du Luxembourg ou Rue Mouffetard, conforme a energia | F42: livre
D43: 15:45 | E43: Hotel → Orly pelo metrô 14 | F43: deslocamento | L43: Sair 2h45 antes do voo; a 14 leva 25 min de Châtelet.
D44: 18:30 | E44: Voo Orly → Porto | F44: deslocamento
E45: Custo do dia 5 | G45: =SUM(G40:G44) -> 62
...

Sheet Reservas
A1: Reservar antes
A2: Progresso | B2: =COUNTIF(E5:E12,"feita")&" de "&COUNTA(A5:A12)&" feitas" -> 0 de 8 feitas
A4: O quê | B4: Urgência | C4: Prazo | D4: Dias restantes | E4: Status | F4: Valor pago (EUR) | G4: Reservar / comprar | H4: Observação
A5: Voos Porto ⇄ Paris Orly (TAP / Transavia / easyJet), 7 e 11/10 | B5: Agora | C5: 46281 | D5: =IF(C5="","",C5-TODAY()) -> 4 | E5: pendente | G5: transavia.com | H5: Compare no Kayak ou Google Flights e compre no site da companhia. Transavia é a mais barata para Orly (ida e volta desde ≈ €66–90 pp; 49 voos/semana); TAP desde ≈ €92. Ryanair para Beauvais sai ≈ €125 de média e o ônibus custa €72 para os dois: não compensa. Só bagagem de mão.
A6: Torre Eiffel pela escada, sáb 10/10 ao entardecer | B6: Agora | C6: 46283 | D6: =IF(C6="","",C6-TODAY()) -> 6 | E6: pendente | G6: toureiffel.paris | H6: Escada vende 40 dias antes — para 10/10 abriu em 31/8. Se esgotou, a bilheteria da escada no local costuma ter vaga fora do pôr do sol.
A7: Ingressos Disney 2 dias / 2 parques, qui 8 e sex 9/10 | B7: Agora | C7: 46285 | D7: =IF(C7="","",C7-TODAY()) -> 8 | E7: pendente | G7: disneylandparis.com | H7: Preço por data: dia útil antes da Toussaint fica na faixa "low" (≈ €154 pp o de 2 dias/2 parques). Compre com data no site oficial. Não compre pacote hotel + ingresso: desde 31/3/2026 os pacotes exigem 2 noites.
A8: B&B Hôtel près de Disneyland Paris, 1 noite (8 → 9/10) | B8: Agora | C8: 46285 | D8: =IF(C8="","",C8-TODAY()) -> 8 | E8: pendente | G8: hotel-bb.com | H8: Parceiro oficial em Magny-le-Hongre: ônibus grátis a cada 20 min das 8h à meia-noite, café incluído, ≈ €90–140 a noite. Reserve o quarto avulso (Booking ou site do B&B) — o pacote da Disney exige 2 noites. Cuidado: o "B&B Marne-la-Vallée Val d'Europe" em Serris é outro hotel, sem ônibus para o parque.
A9: ibis Paris Bastille Opéra 11ème, 3 noites (7, 9 e 10/10) | B9: Agora | C9: 46285 | D9: =IF(C9="","",C9-TODAY()) -> 8 | E9: pendente | G9: all.accor.com | H9: ≈ €105–140 a noite, 7 min a pé da Bastille, RER A na Gare de Lyon. Alternativa 4★: Villa Beaumarchais (Marais, Chemin Vert) se o total no checkout do eDreams ficar abaixo de €130 — a lista mostra €94 'desde', mas outros sites cobram €175+. Duas reservas (quarta; sexta e sábado) — pergunte se guardam a mala na quinta.
A10: Louvre, sáb 10/10 às 9h — tarifa residente | B10: Um mês antes | C10: 46290 | D10: =IF(C10="","",C10-TODAY()) -> 13 | E10: pendente | G10: louvre.fr | H10: Escolha o ingresso de €22 (residente EEE) e leve o título de residência: conferem na entrada.
A11: Orsay, dom 11/10 às 9h30 | B11: Um mês antes | C11: 46290 | D11: =IF(C11="","",C11-TODAY()) -> 13 | E11: pendente | H11: Fecha segunda — por isso é domingo. Primeira entrada evita a fila do meio-dia.
A12: Sainte-Chapelle, qua 7/10 à tarde | B12: 2 a 4 semanas | C12: 46295 | D12: =IF(C12="","",C12-TODAY()) -> 18 | E12: pendente | G12: sainte-chapelle.fr | H12: Com hora marcada a fila cai de 40 min para 5.

Sheet Real
A1: Gastos reais
A2: Total real | B2: =SUM(G5:G205) -> 0
A4: Data | B4: Categoria | C4: Descrição | D4: Valor | E4: Moeda | F4: Ignorar | G4: EUR | H4: Pago por
A5: 46302 | B5: alimentacao | C5: (exemplo — apague ou sobrescreva) Jantar no bouillon | D5: 38.5 | E5: EUR | F5: sim | G5: =IF(OR(D5="",F5="sim"),0,D5*IFERROR(INDEX(Parâmetros!$B$22:$B$22,MATCH(E5,Parâmetros!$A$22:$A$22,0)),1)*(1+IF(E5=Parâmetros!$B$9,0,Parâmetros!$B$14))) -> 0 | H5: cartão
G6: =IF(OR(D6="",F6="sim"),0,D6*IFERROR(INDEX(Parâmetros!$B$22:$B$22,MATCH(E6,Parâmetros!$A$22:$A$22,0)),1)*(1+IF(E6=Parâmetros!$B$9,0,Parâmetros!$B$14))) -> 0
G7: =IF(OR(D7="",F7="sim"),0,D7*IFERROR(INDEX(Parâmetros!$B$22:$B$22,MATCH(E7,Parâmetros!$A$22:$A$22,0)),1)*(1+IF(E7=Parâmetros!$B$9,0,Parâmetros!$B$14))) -> 0
G8: =IF(OR(D8="",F8="sim"),0,D8*IFERROR(INDEX(Parâmetros!$B$22:$B$22,MATCH(E8,Parâmetros!$A$22:$A$22,0)),1)*(1+IF(E8=Parâmetros!$B$9,0,Parâmetros!$B$14))) -> 0
G9: =IF(OR(D9="",F9="sim"),0,D9*IFERROR(INDEX(Parâmetros!$B$22:$B$22,MATCH(E9,Parâmetros!$A$22:$A$22,0)),1)*(1+IF(E9=Parâmetros!$B$9,0,Parâmetros!$B$14))) -> 0
G10: =IF(OR(D10="",F10="sim"),0,D10*IFERROR(INDEX(Parâmetros!$B$22:$B$22,MATCH(E10,Parâmetros!$A$22:$A$22,0)),1)*(1+IF(E10=Parâmetros!$B$9,0,Parâmetros!$B$14))) -> 0
G11: =IF(OR(D11="",F11="sim"),0,D11*IFERROR(INDEX(Parâmetros!$B$22:$B$22,MATCH(E11,Parâmetros!$A$22:$A$22,0)),1)*(1+IF(E11=Parâmetros!$B$9,0,Parâmetros!$B$14))) -> 0
G12: =IF(OR(D12="",F12="sim"),0,D12*IFERROR(INDEX(Parâmetros!$B$22:$B$22,MATCH(E12,Parâmetros!$A$22:$A$22,0)),1)*(1+IF(E12=Parâmetros!$B$9,0,Parâmetros!$B$14))) -> 0
G13: =IF(OR(D13="",F13="sim"),0,D13*IFERROR(INDEX(Parâmetros!$B$22:$B$22,MATCH(E13,Parâmetros!$A$22:$A$22,0)),1)*(1+IF(E13=Parâmetros!$B$9,0,Parâmetros!$B$14))) -> 0
G14: =IF(OR(D14="",F14="sim"),0,D14*IFERROR(INDEX(Parâmetros!$B$22:$B$22,MATCH(E14,Parâmetros!$A$22:$A$22,0)),1)*(1+IF(E14=Parâmetros!$B$9,0,Parâmetros!$B$14))) -> 0
G15: =IF(OR(D15="",F15="sim"),0,D15*IFERROR(INDEX(Parâmetros!$B$22:$B$22,MATCH(E15,Parâmetros!$A$22:$A$22,0)),1)*(1+IF(E15=Parâmetros!$B$9,0,Parâmetros!$B$14))) -> 0
G16: =IF(OR(D16="",F16="sim"),0,D16*IFERROR(INDEX(Parâmetros!$B$22:$B$22,MATCH(E16,Parâmetros!$A$22:$A$22,0)),1)*(1+IF(E16=Parâmetros!$B$9,0,Parâmetros!$B$14))) -> 0
G17: =IF(OR(D17="",F17="sim"),0,D17*IFERROR(INDEX(Parâmetros!$B$22:$B$22,MATCH(E17,Parâmetros!$A$22:$A$22,0)),1)*(1+IF(E17=Parâmetros!$B$9,0,Parâmetros!$B$14))) -> 0
... G205: =IF(OR(D205="",F205="sim"),0,D205*IFERROR(INDEX(Parâmetros!$B$22:$B$22,MATCH(E205,Parâmetros!$A$22:$A$22,0)),1)*(1+IF(E205=Parâmetros!$B$9,0,Parâmetros!$B$14))) -> 0

Sheet Cortes
A1: Onde cortar, na ordem que menos dói
A2: Falta para caber no teto (escolhido com reserva): | D2: =MAX(0,-Resumo!D26) -> 0
A4: Item | B4: Categoria | C4: Opção atual | D4: Escolhido (EUR) | E4: Econômico (EUR) | F4: Economia | G4: Acumulado | H4: Intocável | I4: Já basta?
A5: =Itens!C4 -> ibis Paris Bastille Opéra 11ème | B5: =Itens!B4 -> hospedagem | C5: =Itens!H4 -> plano | D5: =Itens!R4 -> 390 | E5: =Itens!O4 -> 315 | F5: =MAX(0,D5-E5) -> 75 | G5: =SUM($F$5:F5) -> 75 | H5: =Itens!S4 -> não | I5: =IF(AND($D$2>0,G5>=$D$2,TRUE()),"← aqui","")
A6: =Itens!C5 -> B&B Hôtel près de Disneyland Paris (Magny-le-Hongre) | B6: =Itens!B5 -> hospedagem | C6: =Itens!H5 -> plano | D6: =Itens!R5 -> 120 | E6: =Itens!O5 -> 70 | F6: =MAX(0,D6-E6) -> 50 | G6: =SUM($F$5:F6) -> 125 | H6: =Itens!S5 -> não | I6: =IF(AND($D$2>0,G6>=$D$2,G5<$D$2),"← aqui","")
A7: =Itens!C28 -> Estimativa restante — Extras e compras | B7: =Itens!B28 -> extras | C7: =Itens!H28 -> plano | D7: =Itens!R28 -> 80 | E7: =Itens!O28 -> 40 | F7: =MAX(0,D7-E7) -> 40 | G7: =SUM($F$5:F7) -> 165 | H7: =Itens!S28 -> não | I7: =IF(AND($D$2>0,G7>=$D$2,G6<$D$2),"← aqui","")
A8: =Itens!C18 -> Bilhetes de metrô, ≈ 12 viagens | B8: =Itens!B18 -> transporte-local | C8: =Itens!H18 -> plano | D8: =Itens!R18 -> 62 | E8: =Itens!O18 -> 40 | F8: =MAX(0,D8-E8) -> 22 | G8: =SUM($F$5:F8) -> 187 | H8: =Itens!S18 -> não | I8: =IF(AND($D$2>0,G8>=$D$2,G7<$D$2),"← aqui","")
A9: =Itens!C2 -> Voo OPO → ORY (Transavia) | B9: =Itens!B2 -> voos | C9: =Itens!H2 -> plano | D9: =Itens!R2 -> 100 | E9: =Itens!O2 -> 80 | F9: =MAX(0,D9-E9) -> 20 | G9: =SUM($F$5:F9) -> 207 | H9: =Itens!S2 -> não | I9: =IF(AND($D$2>0,G9>=$D$2,G8<$D$2),"← aqui","")
A10: =Itens!C3 -> Voo ORY → OPO (Transavia) | B10: =Itens!B3 -> voos | C10: =Itens!H3 -> plano | D10: =Itens!R3 -> 100 | E10: =Itens!O3 -> 80 | F10: =MAX(0,D10-E10) -> 20 | G10: =SUM($F$5:F10) -> 227 | H10: =Itens!S3 -> não | I10: =IF(AND($D$2>0,G10>=$D$2,G9<$D$2),"← aqui","")
A11: =Itens!C20 -> RER A Paris ⇄ Marne-la-Vallée–Chessy | B11: =Itens!B20 -> transporte-local | C11: =Itens!H20 -> plano | D11: =Itens!R20 -> 10 | E11: =Itens!O20 -> 8.281 | F11: =MAX(0,D11-E11) -> 1.719 | G11: =SUM($F$5:F11) -> 228.719 | H11: =Itens!S20 -> não | I11: =IF(AND($D$2>0,G11>=$D$2,G10<$D$2),"← aqui","")
A12: =Itens!C6 -> Taxa de turismo — Paris | B12: =Itens!B6 -> taxa-turismo | C12: =Itens!H6 -> plano | D12: =Itens!R6 -> 19.5 | E12: =Itens!O6 -> 19.5 | F12: =MAX(0,D12-E12) -> 0 | G12: =SUM($F$5:F12) -> 228.719 | H12: =Itens!S6 -> não | I12: =IF(AND($D$2>0,G12>=$D$2,G11<$D$2),"← aqui","")
A13: =Itens!C7 -> Taxa de turismo — Disneyland Paris | B13: =Itens!B7 -> taxa-turismo | C13: =Itens!H7 -> plano | D13: =Itens!R7 -> 3 | E13: =Itens!O7 -> 3 | F13: =MAX(0,D13-E13) -> 0 | G13: =SUM($F$5:F13) -> 228.719 | H13: =Itens!S7 -> não | I13: =IF(AND($D$2>0,G13>=$D$2,G12<$D$2),"← aqui","")
A14: =Itens!C8 -> Estimativa restante — Taxa de turismo | B14: =Itens!B8 -> taxa-turismo | C14: =Itens!H8 -> plano | D14: =Itens!R8 -> 0.5 | E14: =Itens!O8 -> 0.5 | F14: =MAX(0,D14-E14) -> 0 | G14: =SUM($F$5:F14) -> 228.719 | H14: =Itens!S8 -> não | I14: =IF(AND($D$2>0,G14>=$D$2,G13<$D$2),"← aqui","")
A15: =Itens!C19 -> Orly ⇄ Paris pelo metrô 14 (bilhete aeroporto €14) | B15: =Itens!B19 -> transporte-local | C15: =Itens!H19 -> plano | D15: =Itens!R19 -> 56 | E15: =Itens!O19 -> 56 | F15: =MAX(0,D15-E15) -> 0 | G15: =SUM($F$5:F15) -> 228.719 | H15: =Itens!S19 -> não | I15: =IF(AND($D$2>0,G15>=$D$2,G14<$D$2),"← aqui","")
A16: =Itens!C9 -> Almoço de padaria no Marais: fórmula sanduíche + doce | B16: =Itens!B9 -> alimentacao | C16: =Itens!H9 -> plano | D16: =Itens!R9 -> 18 | E16: =Itens!O9 -> 10.8 | F16: =MAX(0,D16-E16) -> 7.2 | G16: =SUM($F$5:F16) -> 235.919 | H16: =Itens!S9 -> sim | I16: =IF(AND($D$2>0,G16>=$D$2,G15<$D$2),"← aqui","")
A17: =Itens!C10 -> Bouillon Chartier: menu completo por menos de €20 | B17: =Itens!B10 -> alimentacao | C17: =Itens!H10 -> plano | D17: =Itens!R10 -> 38 | E17: =Itens!O10 -> 18 | F17: =MAX(0,D17-E17) -> 20 | G17: =SUM($F$5:F17) -> 255.919 | H17: =Itens!S10 -> sim | I17: =IF(AND($D$2>0,G17>=$D$2,G16<$D$2),"← aqui","")
A18: =Itens!C11 -> Almoço no parque | B18: =Itens!B11 -> alimentacao | C18: =Itens!H11 -> plano | D18: =Itens!R11 -> 50 | E18: =Itens!O11 -> 30 | F18: =MAX(0,D18-E18) -> 20 | G18: =SUM($F$5:F18) -> 275.919 | H18: =Itens!S11 -> sim | I18: =IF(AND($D$2>0,G18>=$D$2,G17<$D$2),"← aqui","")
A19: =Itens!C12 -> Jantar leve perto do hotel | B19: =Itens!B12 -> alimentacao | C19: =Itens!H12 -> plano | D19: =Itens!R12 -> 36 | E19: =Itens!O12 -> 21.6 | F19: =MAX(0,D19-E19) -> 14.4 | G19: =SUM($F$5:F19) -> 290.319 | H19: =Itens!S12 -> sim | I19: =IF(AND($D$2>0,G19>=$D$2,G18<$D$2),"← aqui","")
A20: =Itens!C13 -> Almoço no parque | B20: =Itens!B13 -> alimentacao | C20: =Itens!H13 -> plano | D20: =Itens!R13 -> 50 | E20: =Itens!O13 -> 30 | F20: =MAX(0,D20-E20) -> 20 | G20: =SUM($F$5:F20) -> 310.319 | H20: =Itens!S13 -> sim | I20: =IF(AND($D$2>0,G20>=$D$2,G19<$D$2),"← aqui","")
A21: =Itens!C14 -> Jantar em bistrô do 7e ou Bouillon Pigalle | B21: =Itens!B14 -> alimentacao | C21: =Itens!H14 -> plano | D21: =Itens!R14 -> 44 | E21: =Itens!O14 -> 26.4 | F21: =MAX(0,D21-E21) -> 17.6 | G21: =SUM($F$5:F21) -> 327.919 | H21: =Itens!S14 -> sim | I21: =IF(AND($D$2>0,G21>=$D$2,G20<$D$2),"← aqui","")
A22: =Itens!C15 -> Piquenique nas Tulherias ou padaria da Rue de Rivoli | B22: =Itens!B15 -> alimentacao | C22: =Itens!H15 -> plano | D22: =Itens!R15 -> 20 | E22: =Itens!O15 -> 12 | F22: =MAX(0,D22-E22) -> 8 | G22: =SUM($F$5:F22) -> 335.919 | H22: =Itens!S15 -> sim | I22: =IF(AND($D$2>0,G22>=$D$2,G21<$D$2),"← aqui","")
A23: =Itens!C16 -> Marché d'Aligre: queijo, ostras e um copo no balcão | B23: =Itens!B16 -> alimentacao | C23: =Itens!H16 -> plano | D23: =Itens!R16 -> 30 | E23: =Itens!O16 -> 20 | F23: =MAX(0,D23-E23) -> 10 | G23: =SUM($F$5:F23) -> 345.919 | H23: =Itens!S16 -> sim | I23: =IF(AND($D$2>0,G23>=$D$2,G22<$D$2),"← aqui","")
A24: =Itens!C17 -> Estimativa restante — Alimentação | B24: =Itens!B17 -> alimentacao | C24: =Itens!H17 -> plano | D24: =Itens!R17 -> 94 | E24: =Itens!O17 -> 94 | F24: =MAX(0,D24-E24) -> 0 | G24: =SUM($F$5:F24) -> 345.919 | H24: =Itens!S17 -> sim | I24: =IF(AND($D$2>0,G24>=$D$2,G23<$D$2),"← aqui","")
A25: =Itens!C21 -> Sainte-Chapelle — com hora marcada | B25: =Itens!B21 -> atracoes | C25: =Itens!H21 -> plano | D25: =Itens!R21 -> 26 | E25: =Itens!O21 -> 20 | F25: =MAX(0,D25-E25) -> 6 | G25: =SUM($F$5:F25) -> 351.919 | H25: =Itens!S21 -> sim | I25: =IF(AND($D$2>0,G25>=$D$2,G24<$D$2),"← aqui","")
A26: =Itens!C22 -> Disneyland Park — abertura às 9h30 | B26: =Itens!B22 -> atracoes | C26: =Itens!H22 -> plano | D26: =Itens!R22 -> 300 | E26: =Itens!O22 -> 284 | F26: =MAX(0,D26-E26) -> 16 | G26: =SUM($F$5:F26) -> 367.919 | H26: =Itens!S22 -> sim | I26: =IF(AND($D$2>0,G26>=$D$2,G25<$D$2),"← aqui","")
A27: =Itens!C23 -> Torre Eiffel pela escada, até o 2º andar | B27: =Itens!B23 -> atracoes | C27: =Itens!H23 -> plano | D27: =Itens!R23 -> 29.6 | E27: =Itens!O23 -> 0 | F27: =MAX(0,D27-E27) -> 29.6 | G27: =SUM($F$5:F27) -> 397.519 | H27: =Itens!S23 -> sim | I27: =IF(AND($D$2>0,G27>=$D$2,G26<$D$2),"← aqui","")
A28: =Itens!C24 -> Louvre — entrada 9h, tarifa residente EEE | B28: =Itens!B24 -> atracoes | C28: =Itens!H24 -> plano | D28: =Itens!R24 -> 44 | E28: =Itens!O24 -> 44 | F28: =MAX(0,D28-E28) -> 0 | G28: =SUM($F$5:F28) -> 397.519 | H28: =Itens!S24 -> sim | I28: =IF(AND($D$2>0,G28>=$D$2,G27<$D$2),"← aqui","")
A29: =Itens!C25 -> Orangerie: as Ninfeias de Monet | B29: =Itens!B25 -> atracoes | C29: =Itens!H25 -> plano | D29: =Itens!R25 -> 25 | E29: =Itens!O25 -> 25 | F29: =MAX(0,D29-E29) -> 0 | G29: =SUM($F$5:F29) -> 397.519 | H29: =Itens!S25 -> sim | I29: =IF(AND($D$2>0,G29>=$D$2,G28<$D$2),"← aqui","")
A30: =Itens!C26 -> Musée d'Orsay — entrada 9h30 | B30: =Itens!B26 -> atracoes | C30: =Itens!H26 -> plano | D30: =Itens!R26 -> 32 | E30: =Itens!O26 -> 32 | F30: =MAX(0,D30-E30) -> 0 | G30: =SUM($F$5:F30) -> 397.519 | H30: =Itens!S26 -> sim | I30: =IF(AND($D$2>0,G30>=$D$2,G29<$D$2),"← aqui","")
A31: =Itens!C27 -> Estimativa restante — Atrações | B31: =Itens!B27 -> atracoes | C31: =Itens!H27 -> plano | D31: =Itens!R27 -> 8.4 | E31: =Itens!O27 -> 8.4 | F31: =MAX(0,D31-E31) -> 0 | G31: =SUM($F$5:F31) -> 397.519 | H31: =Itens!S27 -> sim | I31: =IF(AND($D$2>0,G31>=$D$2,G30<$D$2),"← aqui","")
A33: A ordem foi calculada na geração; os valores são vivos. Se você mudar preços na aba Itens, a ordem pode ficar desatualizada — a economia por linha não.
