Workbook

Sheet Comparação
A1: Comparação: outubro-2026
A2: Colunas = viagens. Tudo lê das abas P_/I_/S_ de cada viagem; mude um preço ou uma opção lá e a comparação refaz.
A4: Viagem | B4: Roma & Florença — Outubro 2026 | C4: Paris & Disneyland — Outubro 2026 | D4: Δ última − primeira
A5: Início | B5: =P_italia_outubro_2026!B4 -> 46312 | C5: =P_paris_outubro_2026!B4 -> 46302
A6: Fim | B6: =P_italia_outubro_2026!B5 -> 46319 | C6: =P_paris_outubro_2026!B5 -> 46306
A7: Noites | B7: =P_italia_outubro_2026!B6 -> 7 | C7: =P_paris_outubro_2026!B6 -> 4 | D7: =C7-B7 -> -3
A8: Dias | B8: =P_italia_outubro_2026!B7 -> 8 | C8: =P_paris_outubro_2026!B7 -> 5 | D8: =C8-B8 -> -3
A9: Pessoas | B9: =P_italia_outubro_2026!B8 -> 2 | C9: =P_paris_outubro_2026!B8 -> 2 | D9: =C9-B9 -> 0
A11: Escolhido ★, por categoria (opção marcada em cada item)
A12: Voos | B12: =SUMIFS(I_italia_outubro_2026!$R:$R,I_italia_outubro_2026!$B:$B,"voos") -> 340 | C12: =SUMIFS(I_paris_outubro_2026!$R:$R,I_paris_outubro_2026!$B:$B,"voos") -> 200 | D12: =C12-B12 -> -140
A13: Hospedagem | B13: =SUMIFS(I_italia_outubro_2026!$R:$R,I_italia_outubro_2026!$B:$B,"hospedagem") -> 885 | C13: =SUMIFS(I_paris_outubro_2026!$R:$R,I_paris_outubro_2026!$B:$B,"hospedagem") -> 510 | D13: =C13-B13 -> -375
A14: Taxa de turismo | B14: =SUMIFS(I_italia_outubro_2026!$R:$R,I_italia_outubro_2026!$B:$B,"taxa-turismo") -> 76 | C14: =SUMIFS(I_paris_outubro_2026!$R:$R,I_paris_outubro_2026!$B:$B,"taxa-turismo") -> 23 | D14: =C14-B14 -> -53
A15: Alimentação | B15: =SUMIFS(I_italia_outubro_2026!$R:$R,I_italia_outubro_2026!$B:$B,"alimentacao") -> 520 | C15: =SUMIFS(I_paris_outubro_2026!$R:$R,I_paris_outubro_2026!$B:$B,"alimentacao") -> 380 | D15: =C15-B15 -> -140
A16: Transporte local | B16: =SUMIFS(I_italia_outubro_2026!$R:$R,I_italia_outubro_2026!$B:$B,"transporte-local") -> 126 | C16: =SUMIFS(I_paris_outubro_2026!$R:$R,I_paris_outubro_2026!$B:$B,"transporte-local") -> 128 | D16: =C16-B16 -> 2
A17: Atrações | B17: =SUMIFS(I_italia_outubro_2026!$R:$R,I_italia_outubro_2026!$B:$B,"atracoes") -> 194 | C17: =SUMIFS(I_paris_outubro_2026!$R:$R,I_paris_outubro_2026!$B:$B,"atracoes") -> 465 | D17: =C17-B17 -> 271
A18: Extras | B18: =SUMIFS(I_italia_outubro_2026!$R:$R,I_italia_outubro_2026!$B:$B,"extras") -> 100 | C18: =SUMIFS(I_paris_outubro_2026!$R:$R,I_paris_outubro_2026!$B:$B,"extras") -> 80 | D18: =C18-B18 -> -20
A19: Total escolhido | B19: =SUM(B12:B18) -> 2241 | C19: =SUM(C12:C18) -> 1786 | D19: =C19-B19 -> -455
A20: Reserva para imprevistos | B20: =B19*P_italia_outubro_2026!$B$13 -> 224.1 | C20: =C19*P_paris_outubro_2026!$B$13 -> 178.6 | D20: =C20-B20 -> -45.5
A21: Total com reserva | B21: =B19+B20 -> 2465.1 | C21: =C19+C20 -> 1964.6 | D21: =C21-B21 -> -500.5
A22: Tudo econômico (com reserva) | B22: =S_italia_outubro_2026!B17 -> 2128.5057 | C22: =S_paris_outubro_2026!B17 -> 1527.3291 | D22: =C22-B22 -> -601.17662
A23: Plano (com reserva) | B23: =S_italia_outubro_2026!C17 -> 2465.1 | C23: =S_paris_outubro_2026!C17 -> 1964.6 | D23: =C23-B23 -> -500.5
A24: Tudo upgrade (com reserva) | B24: =S_italia_outubro_2026!E17 -> 2465.1 | C24: =S_paris_outubro_2026!E17 -> 3056.02 | D24: =C24-B24 -> 590.92
A26: Para comparar viagens de tamanhos diferentes
A27: Por pessoa | B27: =B19/P_italia_outubro_2026!$B$8 -> 1120.5 | C27: =C19/P_paris_outubro_2026!$B$8 -> 893 | D27: =C27-B27 -> -227.5
A28: Por dia (grupo) | B28: =B19/P_italia_outubro_2026!$B$7 -> 280.125 | C28: =C19/P_paris_outubro_2026!$B$7 -> 357.2 | D28: =C28-B28 -> 77.075
A29: Por pessoa por dia | B29: =B19/P_italia_outubro_2026!$B$8/P_italia_outubro_2026!$B$7 -> 140.0625 | C29: =C19/P_paris_outubro_2026!$B$8/P_paris_outubro_2026!$B$7 -> 178.6 | D29: =C29-B29 -> 38.5375
A30: Por noite de hospedagem | B30: =IF(P_italia_outubro_2026!$B$6=0,0,SUMIFS(I_italia_outubro_2026!$R:$R,I_italia_outubro_2026!$B:$B,"hospedagem")/P_italia_outubro_2026!$B$6) -> 126.42857 | C30: =IF(P_paris_outubro_2026!$B$6=0,0,SUMIFS(I_paris_outubro_2026!$R:$R,I_paris_outubro_2026!$B:$B,"hospedagem")/P_paris_outubro_2026!$B$6) -> 127.5 | D30: =C30-B30 -> 1.0714286
A31: Voos como % do total | B31: =IF(B19=0,0,B12/B19) -> 0.15171798 | C31: =IF(C19=0,0,C12/C19) -> 0.11198208 | D31: =C31-B31 -> -0.0397359
A33: Teto do grupo | B33: =P_italia_outubro_2026!$B$12 -> 2000 | C33: =P_paris_outubro_2026!$B$12 -> 2000 | D33: =C33-B33 -> 0
A34: Folga contra o teto | B34: =B33-B21 -> -465.1 | C34: =C33-C21 -> 35.4 | D34: =C34-B34 -> 500.5
A35: Veredito | B35: =IF(B34>=0,"cabe, sobram "&TEXT(B34,"#,##0")&" €","faltam "&TEXT(-B34,"#,##0")&" €") -> faltam 465 € | C35: =IF(C34>=0,"cabe, sobram "&TEXT(C34,"#,##0")&" €","faltam "&TEXT(-C34,"#,##0")&" €") -> cabe, sobram 35 €
A37: Mais barata no total: | B37: =INDEX($B$4:$C$4,MATCH(MIN($B$21:$C$21),$B$21:$C$21,0)) -> Paris & Disneyland — Outubro 2026
A38: Mais barata por pessoa por dia: | B38: =INDEX($B$4:$C$4,MATCH(MIN($B$27:$C$27),$B$27:$C$27,0)) -> Paris & Disneyland — Outubro 2026
A40: Por pessoa por dia é a linha justa quando as viagens têm durações diferentes: uma viagem curta e cara pode custar menos no total e mais por dia.
A41: Δ compara a última coluna com a primeira. Com três ou mais viagens, leia as colunas lado a lado.
A42: Para testar uma hipótese (outro hotel, upgrade num ingresso), troque a coluna Opção ▼ na aba I_ da viagem: a linha Escolhido refaz.

Sheet S_italia_outubro_2026
A1: Roma & Florença — Outubro 2026
A2: 17 → 24 de outubro · casal · Roma antiga, Vaticano, Uffizi e muita trattoria, com folga.
A4: Período | B4: =P_italia_outubro_2026!B4 -> 46312 | C4: =P_italia_outubro_2026!B5 -> 46319
A5: Pessoas · noites · dias | B5: =P_italia_outubro_2026!B8 -> 2 | C5: =P_italia_outubro_2026!B6 -> 7 | D5: =P_italia_outubro_2026!B7 -> 8
A7: Categoria | B7: Tudo econômico | C7: Plano | D7: Escolhido ★ | E7: Tudo upgrade | F7: Real | G7: Real − Escolhido | H7: Intocável
A8: =P_italia_outubro_2026!B27 -> Voos | B8: =SUMIFS(I_italia_outubro_2026!$O:$O,I_italia_outubro_2026!$B:$B,P_italia_outubro_2026!$A$27) -> 240.006 | C8: =SUMIFS(I_italia_outubro_2026!$P:$P,I_italia_outubro_2026!$B:$B,P_italia_outubro_2026!$A$27) -> 340 | D8: =SUMIFS(I_italia_outubro_2026!$R:$R,I_italia_outubro_2026!$B:$B,P_italia_outubro_2026!$A$27) -> 340 | E8: =SUMIFS(I_italia_outubro_2026!$Q:$Q,I_italia_outubro_2026!$B:$B,P_italia_outubro_2026!$A$27) -> 340 | H8: =P_italia_outubro_2026!D27 -> não
A9: =P_italia_outubro_2026!B28 -> Hospedagem | B9: =SUMIFS(I_italia_outubro_2026!$O:$O,I_italia_outubro_2026!$B:$B,P_italia_outubro_2026!$A$28) -> 744.993 | C9: =SUMIFS(I_italia_outubro_2026!$P:$P,I_italia_outubro_2026!$B:$B,P_italia_outubro_2026!$A$28) -> 885 | D9: =SUMIFS(I_italia_outubro_2026!$R:$R,I_italia_outubro_2026!$B:$B,P_italia_outubro_2026!$A$28) -> 885 | E9: =SUMIFS(I_italia_outubro_2026!$Q:$Q,I_italia_outubro_2026!$B:$B,P_italia_outubro_2026!$A$28) -> 885 | H9: =P_italia_outubro_2026!D28 -> não
A10: =P_italia_outubro_2026!B29 -> Taxa de turismo | B10: =SUMIFS(I_italia_outubro_2026!$O:$O,I_italia_outubro_2026!$B:$B,P_italia_outubro_2026!$A$29) -> 76 | C10: =SUMIFS(I_italia_outubro_2026!$P:$P,I_italia_outubro_2026!$B:$B,P_italia_outubro_2026!$A$29) -> 76 | D10: =SUMIFS(I_italia_outubro_2026!$R:$R,I_italia_outubro_2026!$B:$B,P_italia_outubro_2026!$A$29) -> 76 | E10: =SUMIFS(I_italia_outubro_2026!$Q:$Q,I_italia_outubro_2026!$B:$B,P_italia_outubro_2026!$A$29) -> 76 | H10: =P_italia_outubro_2026!D29 -> não
A11: =P_italia_outubro_2026!B30 -> Alimentação | B11: =SUMIFS(I_italia_outubro_2026!$O:$O,I_italia_outubro_2026!$B:$B,P_italia_outubro_2026!$A$30) -> 520 | C11: =SUMIFS(I_italia_outubro_2026!$P:$P,I_italia_outubro_2026!$B:$B,P_italia_outubro_2026!$A$30) -> 520 | D11: =SUMIFS(I_italia_outubro_2026!$R:$R,I_italia_outubro_2026!$B:$B,P_italia_outubro_2026!$A$30) -> 520 | E11: =SUMIFS(I_italia_outubro_2026!$Q:$Q,I_italia_outubro_2026!$B:$B,P_italia_outubro_2026!$A$30) -> 520 | H11: =P_italia_outubro_2026!D30 -> sim
A12: =P_italia_outubro_2026!B31 -> Transporte local | B12: =SUMIFS(I_italia_outubro_2026!$O:$O,I_italia_outubro_2026!$B:$B,P_italia_outubro_2026!$A$31) -> 100.0062 | C12: =SUMIFS(I_italia_outubro_2026!$P:$P,I_italia_outubro_2026!$B:$B,P_italia_outubro_2026!$A$31) -> 126 | D12: =SUMIFS(I_italia_outubro_2026!$R:$R,I_italia_outubro_2026!$B:$B,P_italia_outubro_2026!$A$31) -> 126 | E12: =SUMIFS(I_italia_outubro_2026!$Q:$Q,I_italia_outubro_2026!$B:$B,P_italia_outubro_2026!$A$31) -> 126 | H12: =P_italia_outubro_2026!D31 -> não
A13: =P_italia_outubro_2026!B32 -> Atrações | B13: =SUMIFS(I_italia_outubro_2026!$O:$O,I_italia_outubro_2026!$B:$B,P_italia_outubro_2026!$A$32) -> 194 | C13: =SUMIFS(I_italia_outubro_2026!$P:$P,I_italia_outubro_2026!$B:$B,P_italia_outubro_2026!$A$32) -> 194 | D13: =SUMIFS(I_italia_outubro_2026!$R:$R,I_italia_outubro_2026!$B:$B,P_italia_outubro_2026!$A$32) -> 194 | E13: =SUMIFS(I_italia_outubro_2026!$Q:$Q,I_italia_outubro_2026!$B:$B,P_italia_outubro_2026!$A$32) -> 194 | H13: =P_italia_outubro_2026!D32 -> sim
A14: =P_italia_outubro_2026!B33 -> Extras e compras | B14: =SUMIFS(I_italia_outubro_2026!$O:$O,I_italia_outubro_2026!$B:$B,P_italia_outubro_2026!$A$33) -> 60 | C14: =SUMIFS(I_italia_outubro_2026!$P:$P,I_italia_outubro_2026!$B:$B,P_italia_outubro_2026!$A$33) -> 100 | D14: =SUMIFS(I_italia_outubro_2026!$R:$R,I_italia_outubro_2026!$B:$B,P_italia_outubro_2026!$A$33) -> 100 | E14: =SUMIFS(I_italia_outubro_2026!$Q:$Q,I_italia_outubro_2026!$B:$B,P_italia_outubro_2026!$A$33) -> 100 | H14: =P_italia_outubro_2026!D33 -> não
A15: Total previsto | B15: =SUM(B8:B14) -> 1935.0052 | C15: =SUM(C8:C14) -> 2241 | D15: =SUM(D8:D14) -> 2241 | E15: =SUM(E8:E14) -> 2241
A16: Reserva para imprevistos | B16: =B15*P_italia_outubro_2026!$B$13 -> 193.50052 | C16: =C15*P_italia_outubro_2026!$B$13 -> 224.1 | D16: =D15*P_italia_outubro_2026!$B$13 -> 224.1 | E16: =E15*P_italia_outubro_2026!$B$13 -> 224.1
A17: Total com reserva | B17: =B15+B16 -> 2128.5057 | C17: =C15+C16 -> 2465.1 | D17: =D15+D16 -> 2465.1 | E17: =E15+E16 -> 2465.1
A19: Por pessoa | B19: =B15/P_italia_outubro_2026!$B$8 -> 967.5026 | C19: =C15/P_italia_outubro_2026!$B$8 -> 1120.5 | D19: =D15/P_italia_outubro_2026!$B$8 -> 1120.5 | E19: =E15/P_italia_outubro_2026!$B$8 -> 1120.5
A20: Por dia (grupo) | B20: =B15/P_italia_outubro_2026!$B$7 -> 241.87565 | C20: =C15/P_italia_outubro_2026!$B$7 -> 280.125 | D20: =D15/P_italia_outubro_2026!$B$7 -> 280.125 | E20: =E15/P_italia_outubro_2026!$B$7 -> 280.125
A21: Por pessoa por dia | B21: =B15/P_italia_outubro_2026!$B$8/P_italia_outubro_2026!$B$7 -> 120.93783 | C21: =C15/P_italia_outubro_2026!$B$8/P_italia_outubro_2026!$B$7 -> 140.0625 | D21: =D15/P_italia_outubro_2026!$B$8/P_italia_outubro_2026!$B$7 -> 140.0625 | E21: =E15/P_italia_outubro_2026!$B$8/P_italia_outubro_2026!$B$7 -> 140.0625
A22: Gasto em solo (sem voos) | B22: =B15-SUMIFS(I_italia_outubro_2026!$O:$O,I_italia_outubro_2026!$B:$B,"voos") -> 1694.9992 | C22: =C15-SUMIFS(I_italia_outubro_2026!$P:$P,I_italia_outubro_2026!$B:$B,"voos") -> 1901 | D22: =D15-SUMIFS(I_italia_outubro_2026!$R:$R,I_italia_outubro_2026!$B:$B,"voos") -> 1901 | E22: =E15-SUMIFS(I_italia_outubro_2026!$Q:$Q,I_italia_outubro_2026!$B:$B,"voos") -> 1901
A23: Alimentação / gasto em solo | B23: =IF(B22=0,0,SUMIFS(I_italia_outubro_2026!$O:$O,I_italia_outubro_2026!$B:$B,"alimentacao")/B22) -> 0.30678481 | C23: =IF(C22=0,0,SUMIFS(I_italia_outubro_2026!$P:$P,I_italia_outubro_2026!$B:$B,"alimentacao")/C22) -> 0.27354024 | D23: =IF(D22=0,0,SUMIFS(I_italia_outubro_2026!$R:$R,I_italia_outubro_2026!$B:$B,"alimentacao")/D22) -> 0.27354024 | E23: =IF(E22=0,0,SUMIFS(I_italia_outubro_2026!$Q:$Q,I_italia_outubro_2026!$B:$B,"alimentacao")/E22) -> 0.27354024 | H23: meta 15–20%
A25: Teto do grupo | B25: =P_italia_outubro_2026!$B$12 -> 2000 | C25: =P_italia_outubro_2026!$B$12 -> 2000 | D25: =P_italia_outubro_2026!$B$12 -> 2000 | E25: =P_italia_outubro_2026!$B$12 -> 2000
A26: Folga contra o teto | B26: =B25-B17 -> -128.50572 | C26: =C25-C17 -> -465.1 | D26: =D25-D17 -> -465.1 | E26: =E25-E17 -> -465.1
A27: Uso do teto | B27: =IF(B25=0,0,B17/B25) -> 1.0642529 | C27: =IF(C25=0,0,C17/C25) -> 1.23255 | D27: =IF(D25=0,0,D17/D25) -> 1.23255 | E27: =IF(E25=0,0,E17/E25) -> 1.23255
A28: Veredito | B28: =IF(B26>=0,"cabe, sobram "&TEXT(B26,"#,##0")&" €","faltam "&TEXT(-B26,"#,##0")&" €") -> faltam 129 € | C28: =IF(C26>=0,"cabe, sobram "&TEXT(C26,"#,##0")&" €","faltam "&TEXT(-C26,"#,##0")&" €") -> faltam 465 € | D28: =IF(D26>=0,"cabe, sobram "&TEXT(D26,"#,##0")&" €","faltam "&TEXT(-D26,"#,##0")&" €") -> faltam 465 € | E28: =IF(E26>=0,"cabe, sobram "&TEXT(E26,"#,##0")&" €","faltam "&TEXT(-E26,"#,##0")&" €") -> faltam 465 €
A29: Itens em upgrade / econômico | D29: =COUNTIF(I_italia_outubro_2026!$H:$H,"upgrade")&" up · "&COUNTIF(I_italia_outubro_2026!$H:$H,"econômico")&" eco" -> 0 up · 0 eco
A31: Como ler
A32: Escolhido ★ é o seu cenário: soma a opção marcada em cada linha da aba Itens (coluna Opção ▼). Tudo econômico e Tudo upgrade são os dois extremos.
A33: Plano = o roteiro como foi pesquisado. Real soma o que você lançar na aba Real durante a viagem; Real − Escolhido mostra onde estourou.
A34: Linhas rosa são intocáveis: a razão de ser da viagem. Cortar ali é planejar outra viagem.
A35: Nada aqui é digitado: tudo vem de Itens, Parâmetros e Real. Para mudar um número, mude lá.

Sheet P_italia_outubro_2026
A1: Roma & Florença — Outubro 2026
A2: Premissas da viagem. Azul = entrada; amarelo = o que mais mexe no total.
A3: Slug | B3: italia-outubro-2026
A4: Início | B4: 46312
A5: Fim | B5: 46319
A6: Noites | B6: =B5-B4 -> 7 | E6: fórmula
A7: Dias de viagem | B7: =B5-B4+1 -> 8 | E7: fórmula
A8: Pessoas | B8: 2
A9: Moeda de casa | B9: EUR
A10: Teto informado | B10: 2000
A11: Teto é por | B11: total | E11: total | pessoa
A12: Teto do grupo | B12: =IF(B11="pessoa",B10*B8,B10) -> 2000 | E12: fórmula
A13: Reserva para imprevistos (%) | B13: 0.1 | E13: sobre o total escolhido
A14: Margem do cartão fora do euro | B14: 0 | E14: 0% num Revolut/Wise; 1–3% em banco tradicional
A15: Opção padrão dos itens | B15: plano | E15: a coluna Opção da aba Itens decide item a item
A16: Pesquisa de | B16: 46277
A17: Status | B17: arquivado
A20: Câmbio (EUR por 1 unidade da moeda)
A21: Moeda | B21: EUR por 1 | C21: Data | E21: Fonte
A22: EUR | B22: 1 | C22: 46277 | E22: moeda de casa
A25: Categorias | E25: Fator econômico: preço que sobra na opção econômica quando o item não tem uma explícita (0,8 = corta 20%). Intocável força 1.
A26: ID | B26: Nome | C26: Fator econômico | D26: Intocável | E26: De onde veio o número
A27: voos | B27: Voos | C27: 0.7059 | D27: não | E27: Ryanair OPO→FCO e PSA→OPO para 2, cotado a 5 semanas com uma mala de 10 kg cada. Econômico: só bagagem de mão.
A28: hospedagem | B28: Hospedagem | C28: 0.8418 | D28: não | E28: 4 noites B&B em Monti (≈ €120) + 3 em Oltrarno (≈ €135). Econômico: quarto em apartamento a €100/€115.
A29: taxa-turismo | B29: Taxa de turismo | C29: 1 | D29: não | E29: Roma €5 e Florença €6 por pessoa por noite, no check-in.
A30: alimentacao | B30: Alimentação | C30: 1 | D30: sim | E30: €65 por dia para o casal: bar de manhã, mercado ao meio-dia, trattoria à noite. Comer bem é o motivo da viagem — não corta.
A31: transporte-local | B31: Transporte local | C31: 0.7937 | D31: não | E31: FL1 do aeroporto, ATAC, Roma→Florença antecipado, Florença→Pisa. Econômico: Italo Low Cost.
A32: atracoes | B32: Atrações | C32: 1 | D32: sim | E32: Coliseu, Vaticano, Uffizi, Accademia, Pantheon para 2. Econômico: Uffizi no ingresso da tarde.
A33: extras | B33: Extras e compras | C33: 0.6 | D33: não | E33: Teto assumido — diga o seu. Pompeia, se entrar, são +€130 aqui.

Sheet I_italia_outubro_2026
A1: ID | B1: Categoria | C1: Item | D1: Quando | E1: Qtd | F1: Unidade | G1: Moeda | H1: Opção ▼ | I1: Preço econômico | J1: Preço plano | K1: Preço upgrade | L1: Preço escolhido | M1: × (pessoas/noites) | N1: Câmbio + margem | O1: Total econômico (EUR) | P1: Total plano (EUR) | Q1: Total upgrade (EUR) | R1: Total escolhido (EUR) | S1: Intocável | T1: Dia | U1: Reservar / comprar | V1: O que é o econômico | W1: O que é o upgrade | X1: Fonte / observação
A2: voo:ida | B2: voos | C2: Voo OPO → FCO (Ryanair) | D2: 46312 | E2: 1 | F2: pessoa | G2: EUR | H2: plano | I2: =J2*IFERROR(INDEX(P_italia_outubro_2026!$C$27:$C$33,MATCH(B2,P_italia_outubro_2026!$A$27:$A$33,0)),1) -> 67.0605 | J2: 95 | K2: =J2 -> 95 | L2: =IF(H2="econômico",I2,IF(H2="upgrade",K2,J2)) -> 95 | M2: =E2*IF(OR(F2="pessoa",F2="pessoa-noite"),P_italia_outubro_2026!$B$8,1) -> 2 | N2: =IFERROR(INDEX(P_italia_outubro_2026!$B$22:$B$22,MATCH(G2,P_italia_outubro_2026!$A$22:$A$22,0)),1)*(1+IF(G2=P_italia_outubro_2026!$B$9,0,P_italia_outubro_2026!$B$14)) -> 1 | O2: =M2*I2*N2 -> 134.121 | P2: =M2*J2*N2 -> 190 | Q2: =M2*K2*N2 -> 190 | R2: =M2*L2*N2 -> 190 | S2: =IFERROR(INDEX(P_italia_outubro_2026!$D$27:$D$33,MATCH(B2,P_italia_outubro_2026!$A$27:$A$33,0)),"não") -> não | V2: — (preço plano × fator da categoria) | W2: — (sem upgrade pesquisado) | X2: status: cotado
A3: voo:volta | B3: voos | C3: Voo PSA → OPO (Ryanair) | D3: 46319 | E3: 1 | F3: pessoa | G3: EUR | H3: plano | I3: =J3*IFERROR(INDEX(P_italia_outubro_2026!$C$27:$C$33,MATCH(B3,P_italia_outubro_2026!$A$27:$A$33,0)),1) -> 52.9425 | J3: 75 | K3: =J3 -> 75 | L3: =IF(H3="econômico",I3,IF(H3="upgrade",K3,J3)) -> 75 | M3: =E3*IF(OR(F3="pessoa",F3="pessoa-noite"),P_italia_outubro_2026!$B$8,1) -> 2 | N3: =IFERROR(INDEX(P_italia_outubro_2026!$B$22:$B$22,MATCH(G3,P_italia_outubro_2026!$A$22:$A$22,0)),1)*(1+IF(G3=P_italia_outubro_2026!$B$9,0,P_italia_outubro_2026!$B$14)) -> 1 | O3: =M3*I3*N3 -> 105.885 | P3: =M3*J3*N3 -> 150 | Q3: =M3*K3*N3 -> 150 | R3: =M3*L3*N3 -> 150 | S3: =IFERROR(INDEX(P_italia_outubro_2026!$D$27:$D$33,MATCH(B3,P_italia_outubro_2026!$A$27:$A$33,0)),"não") -> não | V3: — (preço plano × fator da categoria) | W3: — (sem upgrade pesquisado) | X3: status: cotado
A4: hosp:hosp-roma | B4: hospedagem | C4: B&B em Monti (a escolher) | D4: 46312 | E4: 4 | F4: noite | G4: EUR | H4: plano | I4: =J4*IFERROR(INDEX(P_italia_outubro_2026!$C$27:$C$33,MATCH(B4,P_italia_outubro_2026!$A$27:$A$33,0)),1) -> 101.016 | J4: 120 | K4: =J4 -> 120 | L4: =IF(H4="econômico",I4,IF(H4="upgrade",K4,J4)) -> 120 | M4: =E4*IF(OR(F4="pessoa",F4="pessoa-noite"),P_italia_outubro_2026!$B$8,1) -> 4 | N4: =IFERROR(INDEX(P_italia_outubro_2026!$B$22:$B$22,MATCH(G4,P_italia_outubro_2026!$A$22:$A$22,0)),1)*(1+IF(G4=P_italia_outubro_2026!$B$9,0,P_italia_outubro_2026!$B$14)) -> 1 | O4: =M4*I4*N4 -> 404.064 | P4: =M4*J4*N4 -> 480 | Q4: =M4*K4*N4 -> 480 | R4: =M4*L4*N4 -> 480 | S4: =IFERROR(INDEX(P_italia_outubro_2026!$D$27:$D$33,MATCH(B4,P_italia_outubro_2026!$A$27:$A$33,0)),"não") -> não | V4: — (preço plano × fator da categoria) | W4: — (sem upgrade pesquisado) | X4: Quinze minutos a pé do Coliseu, metrô Cavour na porta, e bar de bairro para o café. Sem a fila de Termini nem o preço do centro histórico.
A5: hosp:hosp-florenca | B5: hospedagem | C5: B&B em Oltrarno / Santo Spirito (a escolher) | D5: 46316 | E5: 3 | F5: noite | G5: EUR | H5: plano | I5: =J5*IFERROR(INDEX(P_italia_outubro_2026!$C$27:$C$33,MATCH(B5,P_italia_outubro_2026!$A$27:$A$33,0)),1) -> 113.643 | J5: 135 | K5: =J5 -> 135 | L5: =IF(H5="econômico",I5,IF(H5="upgrade",K5,J5)) -> 135 | M5: =E5*IF(OR(F5="pessoa",F5="pessoa-noite"),P_italia_outubro_2026!$B$8,1) -> 3 | N5: =IFERROR(INDEX(P_italia_outubro_2026!$B$22:$B$22,MATCH(G5,P_italia_outubro_2026!$A$22:$A$22,0)),1)*(1+IF(G5=P_italia_outubro_2026!$B$9,0,P_italia_outubro_2026!$B$14)) -> 1 | O5: =M5*I5*N5 -> 340.929 | P5: =M5*J5*N5 -> 405 | Q5: =M5*K5*N5 -> 405 | R5: =M5*L5*N5 -> 405 | S5: =IFERROR(INDEX(P_italia_outubro_2026!$D$27:$D$33,MATCH(B5,P_italia_outubro_2026!$A$27:$A$33,0)),"não") -> não | V5: — (preço plano × fator da categoria) | W5: — (sem upgrade pesquisado) | X5: O lado tranquilo do rio: trattoria de bairro na praça, dez minutos a pé dos Uffizi, e o Piazzale Michelangelo subindo a rua.
A6: taxa:hosp-roma | B6: taxa-turismo | C6: Taxa de turismo — Roma | D6: 46312 | E6: 4 | F6: pessoa-noite | G6: EUR | H6: plano | I6: =J6*IFERROR(INDEX(P_italia_outubro_2026!$C$27:$C$33,MATCH(B6,P_italia_outubro_2026!$A$27:$A$33,0)),1) -> 5 | J6: 5 | K6: =J6 -> 5 | L6: =IF(H6="econômico",I6,IF(H6="upgrade",K6,J6)) -> 5 | M6: =E6*IF(OR(F6="pessoa",F6="pessoa-noite"),P_italia_outubro_2026!$B$8,1) -> 8 | N6: =IFERROR(INDEX(P_italia_outubro_2026!$B$22:$B$22,MATCH(G6,P_italia_outubro_2026!$A$22:$A$22,0)),1)*(1+IF(G6=P_italia_outubro_2026!$B$9,0,P_italia_outubro_2026!$B$14)) -> 1 | O6: =M6*I6*N6 -> 40 | P6: =M6*J6*N6 -> 40 | Q6: =M6*K6*N6 -> 40 | R6: =M6*L6*N6 -> 40 | S6: =IFERROR(INDEX(P_italia_outubro_2026!$D$27:$D$33,MATCH(B6,P_italia_outubro_2026!$A$27:$A$33,0)),"não") -> não | V6: — (preço plano × fator da categoria) | W6: — (sem upgrade pesquisado) | X6: cobrada no check-in, por pessoa por noite
A7: taxa:hosp-florenca | B7: taxa-turismo | C7: Taxa de turismo — Florença | D7: 46316 | E7: 3 | F7: pessoa-noite | G7: EUR | H7: plano | I7: =J7*IFERROR(INDEX(P_italia_outubro_2026!$C$27:$C$33,MATCH(B7,P_italia_outubro_2026!$A$27:$A$33,0)),1) -> 6 | J7: 6 | K7: =J7 -> 6 | L7: =IF(H7="econômico",I7,IF(H7="upgrade",K7,J7)) -> 6 | M7: =E7*IF(OR(F7="pessoa",F7="pessoa-noite"),P_italia_outubro_2026!$B$8,1) -> 6 | N7: =IFERROR(INDEX(P_italia_outubro_2026!$B$22:$B$22,MATCH(G7,P_italia_outubro_2026!$A$22:$A$22,0)),1)*(1+IF(G7=P_italia_outubro_2026!$B$9,0,P_italia_outubro_2026!$B$14)) -> 1 | O7: =M7*I7*N7 -> 36 | P7: =M7*J7*N7 -> 36 | Q7: =M7*K7*N7 -> 36 | R7: =M7*L7*N7 -> 36 | S7: =IFERROR(INDEX(P_italia_outubro_2026!$D$27:$D$33,MATCH(B7,P_italia_outubro_2026!$A$27:$A$33,0)),"não") -> não | V7: — (preço plano × fator da categoria) | W7: — (sem upgrade pesquisado) | X7: cobrada no check-in, por pessoa por noite
A8: dia1:r2 | B8: alimentacao | C8: Almoço tardio em Monti: pizza al taglio | D8: 46312 | E8: 1 | F8: pessoa | G8: EUR | H8: plano | I8: =J8*IFERROR(INDEX(P_italia_outubro_2026!$C$27:$C$33,MATCH(B8,P_italia_outubro_2026!$A$27:$A$33,0)),1) -> 8 | J8: 8 | K8: =J8 -> 8 | L8: =IF(H8="econômico",I8,IF(H8="upgrade",K8,J8)) -> 8 | M8: =E8*IF(OR(F8="pessoa",F8="pessoa-noite"),P_italia_outubro_2026!$B$8,1) -> 2 | N8: =IFERROR(INDEX(P_italia_outubro_2026!$B$22:$B$22,MATCH(G8,P_italia_outubro_2026!$A$22:$A$22,0)),1)*(1+IF(G8=P_italia_outubro_2026!$B$9,0,P_italia_outubro_2026!$B$14)) -> 1 | O8: =M8*I8*N8 -> 16 | P8: =M8*J8*N8 -> 16 | Q8: =M8*K8*N8 -> 16 | R8: =M8*L8*N8 -> 16 | S8: =IFERROR(INDEX(P_italia_outubro_2026!$D$27:$D$33,MATCH(B8,P_italia_outubro_2026!$A$27:$A$33,0)),"não") -> sim | T8: 1 | V8: — (preço plano × fator da categoria) | W8: — (sem upgrade pesquisado)
A9: dia1:r5 | B9: alimentacao | C9: Trattoria em Trastevere: cacio e pepe e carbonara | D9: 46312 | E9: 1 | F9: pessoa | G9: EUR | H9: plano | I9: =J9*IFERROR(INDEX(P_italia_outubro_2026!$C$27:$C$33,MATCH(B9,P_italia_outubro_2026!$A$27:$A$33,0)),1) -> 32 | J9: 32 | K9: =J9 -> 32 | L9: =IF(H9="econômico",I9,IF(H9="upgrade",K9,J9)) -> 32 | M9: =E9*IF(OR(F9="pessoa",F9="pessoa-noite"),P_italia_outubro_2026!$B$8,1) -> 2 | N9: =IFERROR(INDEX(P_italia_outubro_2026!$B$22:$B$22,MATCH(G9,P_italia_outubro_2026!$A$22:$A$22,0)),1)*(1+IF(G9=P_italia_outubro_2026!$B$9,0,P_italia_outubro_2026!$B$14)) -> 1 | O9: =M9*I9*N9 -> 64 | P9: =M9*J9*N9 -> 64 | Q9: =M9*K9*N9 -> 64 | R9: =M9*L9*N9 -> 64 | S9: =IFERROR(INDEX(P_italia_outubro_2026!$D$27:$D$33,MATCH(B9,P_italia_outubro_2026!$A$27:$A$33,0)),"não") -> sim | T9: 1 | V9: — (preço plano × fator da categoria) | W9: — (sem upgrade pesquisado) | X9: Fuja da Piazza di Santa Maria; duas ruas para dentro o preço cai e a comida melhora.
A10: dia2:r11 | B10: alimentacao | C10: Jantar em Testaccio: trattoria de bairro | D10: 46313 | E10: 1 | F10: pessoa | G10: EUR | H10: plano | I10: =J10*IFERROR(INDEX(P_italia_outubro_2026!$C$27:$C$33,MATCH(B10,P_italia_outubro_2026!$A$27:$A$33,0)),1) -> 30 | J10: 30 | K10: =J10 -> 30 | L10: =IF(H10="econômico",I10,IF(H10="upgrade",K10,J10)) -> 30 | M10: =E10*IF(OR(F10="pessoa",F10="pessoa-noite"),P_italia_outubro_2026!$B$8,1) -> 2 | N10: =IFERROR(INDEX(P_italia_outubro_2026!$B$22:$B$22,MATCH(G10,P_italia_outubro_2026!$A$22:$A$22,0)),1)*(1+IF(G10=P_italia_outubro_2026!$B$9,0,P_italia_outubro_2026!$B$14)) -> 1 | O10: =M10*I10*N10 -> 60 | P10: =M10*J10*N10 -> 60 | Q10: =M10*K10*N10 -> 60 | R10: =M10*L10*N10 -> 60 | S10: =IFERROR(INDEX(P_italia_outubro_2026!$D$27:$D$33,MATCH(B10,P_italia_outubro_2026!$A$27:$A$33,0)),"não") -> sim | T10: 2 | V10: — (preço plano × fator da categoria) | W10: — (sem upgrade pesquisado)
A11: dia2:r8 | B11: alimentacao | C11: Almoço em Monti: trapizzino ou supplì | D11: 46313 | E11: 1 | F11: pessoa | G11: EUR | H11: plano | I11: =J11*IFERROR(INDEX(P_italia_outubro_2026!$C$27:$C$33,MATCH(B11,P_italia_outubro_2026!$A$27:$A$33,0)),1) -> 10 | J11: 10 | K11: =J11 -> 10 | L11: =IF(H11="econômico",I11,IF(H11="upgrade",K11,J11)) -> 10 | M11: =E11*IF(OR(F11="pessoa",F11="pessoa-noite"),P_italia_outubro_2026!$B$8,1) -> 2 | N11: =IFERROR(INDEX(P_italia_outubro_2026!$B$22:$B$22,MATCH(G11,P_italia_outubro_2026!$A$22:$A$22,0)),1)*(1+IF(G11=P_italia_outubro_2026!$B$9,0,P_italia_outubro_2026!$B$14)) -> 1 | O11: =M11*I11*N11 -> 20 | P11: =M11*J11*N11 -> 20 | Q11: =M11*K11*N11 -> 20 | R11: =M11*L11*N11 -> 20 | S11: =IFERROR(INDEX(P_italia_outubro_2026!$D$27:$D$33,MATCH(B11,P_italia_outubro_2026!$A$27:$A$33,0)),"não") -> sim | T11: 2 | V11: — (preço plano × fator da categoria) | W11: — (sem upgrade pesquisado)
A12: dia3:r14 | B12: alimentacao | C12: Almoço em Borgo Pio, longe da fila | D12: 46314 | E12: 1 | F12: pessoa | G12: EUR | H12: plano | I12: =J12*IFERROR(INDEX(P_italia_outubro_2026!$C$27:$C$33,MATCH(B12,P_italia_outubro_2026!$A$27:$A$33,0)),1) -> 15 | J12: 15 | K12: =J12 -> 15 | L12: =IF(H12="econômico",I12,IF(H12="upgrade",K12,J12)) -> 15 | M12: =E12*IF(OR(F12="pessoa",F12="pessoa-noite"),P_italia_outubro_2026!$B$8,1) -> 2 | N12: =IFERROR(INDEX(P_italia_outubro_2026!$B$22:$B$22,MATCH(G12,P_italia_outubro_2026!$A$22:$A$22,0)),1)*(1+IF(G12=P_italia_outubro_2026!$B$9,0,P_italia_outubro_2026!$B$14)) -> 1 | O12: =M12*I12*N12 -> 30 | P12: =M12*J12*N12 -> 30 | Q12: =M12*K12*N12 -> 30 | R12: =M12*L12*N12 -> 30 | S12: =IFERROR(INDEX(P_italia_outubro_2026!$D$27:$D$33,MATCH(B12,P_italia_outubro_2026!$A$27:$A$33,0)),"não") -> sim | T12: 3 | V12: — (preço plano × fator da categoria) | W12: — (sem upgrade pesquisado)
A13: dia3:r16 | B13: alimentacao | C13: Aperitivo e jantar leve no Campo de' Fiori / Jewish Ghetto | D13: 46314 | E13: 1 | F13: pessoa | G13: EUR | H13: plano | I13: =J13*IFERROR(INDEX(P_italia_outubro_2026!$C$27:$C$33,MATCH(B13,P_italia_outubro_2026!$A$27:$A$33,0)),1) -> 28 | J13: 28 | K13: =J13 -> 28 | L13: =IF(H13="econômico",I13,IF(H13="upgrade",K13,J13)) -> 28 | M13: =E13*IF(OR(F13="pessoa",F13="pessoa-noite"),P_italia_outubro_2026!$B$8,1) -> 2 | N13: =IFERROR(INDEX(P_italia_outubro_2026!$B$22:$B$22,MATCH(G13,P_italia_outubro_2026!$A$22:$A$22,0)),1)*(1+IF(G13=P_italia_outubro_2026!$B$9,0,P_italia_outubro_2026!$B$14)) -> 1 | O13: =M13*I13*N13 -> 56 | P13: =M13*J13*N13 -> 56 | Q13: =M13*K13*N13 -> 56 | R13: =M13*L13*N13 -> 56 | S13: =IFERROR(INDEX(P_italia_outubro_2026!$D$27:$D$33,MATCH(B13,P_italia_outubro_2026!$A$27:$A$33,0)),"não") -> sim | T13: 3 | V13: — (preço plano × fator da categoria) | W13: — (sem upgrade pesquisado) | X13: No Ghetto: carciofo alla giudia. Evite as mesas na praça — preço de vitrine.
A14: dia4:r17 | B14: alimentacao | C14: Mercato di Testaccio: Mordi e Vai (sanduíche de allesso) | D14: 46315 | E14: 1 | F14: pessoa | G14: EUR | H14: plano | I14: =J14*IFERROR(INDEX(P_italia_outubro_2026!$C$27:$C$33,MATCH(B14,P_italia_outubro_2026!$A$27:$A$33,0)),1) -> 8 | J14: 8 | K14: =J14 -> 8 | L14: =IF(H14="econômico",I14,IF(H14="upgrade",K14,J14)) -> 8 | M14: =E14*IF(OR(F14="pessoa",F14="pessoa-noite"),P_italia_outubro_2026!$B$8,1) -> 2 | N14: =IFERROR(INDEX(P_italia_outubro_2026!$B$22:$B$22,MATCH(G14,P_italia_outubro_2026!$A$22:$A$22,0)),1)*(1+IF(G14=P_italia_outubro_2026!$B$9,0,P_italia_outubro_2026!$B$14)) -> 1 | O14: =M14*I14*N14 -> 16 | P14: =M14*J14*N14 -> 16 | Q14: =M14*K14*N14 -> 16 | R14: =M14*L14*N14 -> 16 | S14: =IFERROR(INDEX(P_italia_outubro_2026!$D$27:$D$33,MATCH(B14,P_italia_outubro_2026!$A$27:$A$33,0)),"não") -> sim | T14: 4 | V14: — (preço plano × fator da categoria) | W14: — (sem upgrade pesquisado) | X14: Mercado fecha às 15h e não abre domingo. O box 15 é o Mordi e Vai; fila anda rápido.
A15: dia4:r20 | B15: alimentacao | C15: Jantar de despedida de Roma: pizza romana fina | D15: 46315 | E15: 1 | F15: pessoa | G15: EUR | H15: plano | I15: =J15*IFERROR(INDEX(P_italia_outubro_2026!$C$27:$C$33,MATCH(B15,P_italia_outubro_2026!$A$27:$A$33,0)),1) -> 22 | J15: 22 | K15: =J15 -> 22 | L15: =IF(H15="econômico",I15,IF(H15="upgrade",K15,J15)) -> 22 | M15: =E15*IF(OR(F15="pessoa",F15="pessoa-noite"),P_italia_outubro_2026!$B$8,1) -> 2 | N15: =IFERROR(INDEX(P_italia_outubro_2026!$B$22:$B$22,MATCH(G15,P_italia_outubro_2026!$A$22:$A$22,0)),1)*(1+IF(G15=P_italia_outubro_2026!$B$9,0,P_italia_outubro_2026!$B$14)) -> 1 | O15: =M15*I15*N15 -> 44 | P15: =M15*J15*N15 -> 44 | Q15: =M15*K15*N15 -> 44 | R15: =M15*L15*N15 -> 44 | S15: =IFERROR(INDEX(P_italia_outubro_2026!$D$27:$D$33,MATCH(B15,P_italia_outubro_2026!$A$27:$A$33,0)),"não") -> sim | T15: 4 | V15: — (preço plano × fator da categoria) | W15: — (sem upgrade pesquisado)
A16: dia5:f3 | B16: alimentacao | C16: Lampredotto ou schiacciata num balcão do Oltrarno | D16: 46316 | E16: 1 | F16: pessoa | G16: EUR | H16: plano | I16: =J16*IFERROR(INDEX(P_italia_outubro_2026!$C$27:$C$33,MATCH(B16,P_italia_outubro_2026!$A$27:$A$33,0)),1) -> 7 | J16: 7 | K16: =J16 -> 7 | L16: =IF(H16="econômico",I16,IF(H16="upgrade",K16,J16)) -> 7 | M16: =E16*IF(OR(F16="pessoa",F16="pessoa-noite"),P_italia_outubro_2026!$B$8,1) -> 2 | N16: =IFERROR(INDEX(P_italia_outubro_2026!$B$22:$B$22,MATCH(G16,P_italia_outubro_2026!$A$22:$A$22,0)),1)*(1+IF(G16=P_italia_outubro_2026!$B$9,0,P_italia_outubro_2026!$B$14)) -> 1 | O16: =M16*I16*N16 -> 14 | P16: =M16*J16*N16 -> 14 | Q16: =M16*K16*N16 -> 14 | R16: =M16*L16*N16 -> 14 | S16: =IFERROR(INDEX(P_italia_outubro_2026!$D$27:$D$33,MATCH(B16,P_italia_outubro_2026!$A$27:$A$33,0)),"não") -> sim | T16: 5 | V16: — (preço plano × fator da categoria) | W16: — (sem upgrade pesquisado)
A17: dia5:f5 | B17: alimentacao | C17: Trattoria na Piazza Santo Spirito: ribollita, pappa al pomodoro | D17: 46316 | E17: 1 | F17: pessoa | G17: EUR | H17: plano | I17: =J17*IFERROR(INDEX(P_italia_outubro_2026!$C$27:$C$33,MATCH(B17,P_italia_outubro_2026!$A$27:$A$33,0)),1) -> 30 | J17: 30 | K17: =J17 -> 30 | L17: =IF(H17="econômico",I17,IF(H17="upgrade",K17,J17)) -> 30 | M17: =E17*IF(OR(F17="pessoa",F17="pessoa-noite"),P_italia_outubro_2026!$B$8,1) -> 2 | N17: =IFERROR(INDEX(P_italia_outubro_2026!$B$22:$B$22,MATCH(G17,P_italia_outubro_2026!$A$22:$A$22,0)),1)*(1+IF(G17=P_italia_outubro_2026!$B$9,0,P_italia_outubro_2026!$B$14)) -> 1 | O17: =M17*I17*N17 -> 60 | P17: =M17*J17*N17 -> 60 | Q17: =M17*K17*N17 -> 60 | R17: =M17*L17*N17 -> 60 | S17: =IFERROR(INDEX(P_italia_outubro_2026!$D$27:$D$33,MATCH(B17,P_italia_outubro_2026!$A$27:$A$33,0)),"não") -> sim | T17: 5 | V17: — (preço plano × fator da categoria) | W17: — (sem upgrade pesquisado) | X17: A praça fica viva à noite; sente do lado da igreja.
A18: dia6:f11 | B18: alimentacao | C18: Jantar em San Frediano | D18: 46317 | E18: 1 | F18: pessoa | G18: EUR | H18: plano | I18: =J18*IFERROR(INDEX(P_italia_outubro_2026!$C$27:$C$33,MATCH(B18,P_italia_outubro_2026!$A$27:$A$33,0)),1) -> 32 | J18: 32 | K18: =J18 -> 32 | L18: =IF(H18="econômico",I18,IF(H18="upgrade",K18,J18)) -> 32 | M18: =E18*IF(OR(F18="pessoa",F18="pessoa-noite"),P_italia_outubro_2026!$B$8,1) -> 2 | N18: =IFERROR(INDEX(P_italia_outubro_2026!$B$22:$B$22,MATCH(G18,P_italia_outubro_2026!$A$22:$A$22,0)),1)*(1+IF(G18=P_italia_outubro_2026!$B$9,0,P_italia_outubro_2026!$B$14)) -> 1 | O18: =M18*I18*N18 -> 64 | P18: =M18*J18*N18 -> 64 | Q18: =M18*K18*N18 -> 64 | R18: =M18*L18*N18 -> 64 | S18: =IFERROR(INDEX(P_italia_outubro_2026!$D$27:$D$33,MATCH(B18,P_italia_outubro_2026!$A$27:$A$33,0)),"não") -> sim | T18: 6 | V18: — (preço plano × fator da categoria) | W18: — (sem upgrade pesquisado)
A19: dia6:f8 | B19: alimentacao | C19: Mercato Centrale (andar de cima) ou All'Antico Vinaio | D19: 46317 | E19: 1 | F19: pessoa | G19: EUR | H19: plano | I19: =J19*IFERROR(INDEX(P_italia_outubro_2026!$C$27:$C$33,MATCH(B19,P_italia_outubro_2026!$A$27:$A$33,0)),1) -> 12 | J19: 12 | K19: =J19 -> 12 | L19: =IF(H19="econômico",I19,IF(H19="upgrade",K19,J19)) -> 12 | M19: =E19*IF(OR(F19="pessoa",F19="pessoa-noite"),P_italia_outubro_2026!$B$8,1) -> 2 | N19: =IFERROR(INDEX(P_italia_outubro_2026!$B$22:$B$22,MATCH(G19,P_italia_outubro_2026!$A$22:$A$22,0)),1)*(1+IF(G19=P_italia_outubro_2026!$B$9,0,P_italia_outubro_2026!$B$14)) -> 1 | O19: =M19*I19*N19 -> 24 | P19: =M19*J19*N19 -> 24 | Q19: =M19*K19*N19 -> 24 | R19: =M19*L19*N19 -> 24 | S19: =IFERROR(INDEX(P_italia_outubro_2026!$D$27:$D$33,MATCH(B19,P_italia_outubro_2026!$A$27:$A$33,0)),"não") -> sim | T19: 6 | V19: — (preço plano × fator da categoria) | W19: — (sem upgrade pesquisado)
A20: dia7:f14 | B20: alimentacao | C20: Mercato di Sant'Ambrogio: almoço no balcão | D20: 46318 | E20: 1 | F20: pessoa | G20: EUR | H20: plano | I20: =J20*IFERROR(INDEX(P_italia_outubro_2026!$C$27:$C$33,MATCH(B20,P_italia_outubro_2026!$A$27:$A$33,0)),1) -> 12 | J20: 12 | K20: =J20 -> 12 | L20: =IF(H20="econômico",I20,IF(H20="upgrade",K20,J20)) -> 12 | M20: =E20*IF(OR(F20="pessoa",F20="pessoa-noite"),P_italia_outubro_2026!$B$8,1) -> 2 | N20: =IFERROR(INDEX(P_italia_outubro_2026!$B$22:$B$22,MATCH(G20,P_italia_outubro_2026!$A$22:$A$22,0)),1)*(1+IF(G20=P_italia_outubro_2026!$B$9,0,P_italia_outubro_2026!$B$14)) -> 1 | O20: =M20*I20*N20 -> 24 | P20: =M20*J20*N20 -> 24 | Q20: =M20*K20*N20 -> 24 | R20: =M20*L20*N20 -> 24 | S20: =IFERROR(INDEX(P_italia_outubro_2026!$D$27:$D$33,MATCH(B20,P_italia_outubro_2026!$A$27:$A$33,0)),"não") -> sim | T20: 7 | V20: — (preço plano × fator da categoria) | W20: — (sem upgrade pesquisado) | X20: O mercado dos florentinos, sem turista. Fecha às 14h.
A21: dia7:f16 | B21: alimentacao | C21: Jantar de despedida: bistecca alla fiorentina para dois | D21: 46318 | E21: 1 | F21: pessoa | G21: EUR | H21: plano | I21: =J21*IFERROR(INDEX(P_italia_outubro_2026!$C$27:$C$33,MATCH(B21,P_italia_outubro_2026!$A$27:$A$33,0)),1) -> 40 | J21: 40 | K21: =J21 -> 40 | L21: =IF(H21="econômico",I21,IF(H21="upgrade",K21,J21)) -> 40 | M21: =E21*IF(OR(F21="pessoa",F21="pessoa-noite"),P_italia_outubro_2026!$B$8,1) -> 2 | N21: =IFERROR(INDEX(P_italia_outubro_2026!$B$22:$B$22,MATCH(G21,P_italia_outubro_2026!$A$22:$A$22,0)),1)*(1+IF(G21=P_italia_outubro_2026!$B$9,0,P_italia_outubro_2026!$B$14)) -> 1 | O21: =M21*I21*N21 -> 80 | P21: =M21*J21*N21 -> 80 | Q21: =M21*K21*N21 -> 80 | R21: =M21*L21*N21 -> 80 | S21: =IFERROR(INDEX(P_italia_outubro_2026!$D$27:$D$33,MATCH(B21,P_italia_outubro_2026!$A$27:$A$33,0)),"não") -> sim | T21: 7 | V21: — (preço plano × fator da categoria) | W21: — (sem upgrade pesquisado) | X21: Pede-se por peso, 1 kg para dois. É o gasto de comida que vale a viagem.
A22: dia8:f17 | B22: alimentacao | C22: Café da manhã longo na Piazza Santo Spirito | D22: 46319 | E22: 1 | F22: pessoa | G22: EUR | H22: plano | I22: =J22*IFERROR(INDEX(P_italia_outubro_2026!$C$27:$C$33,MATCH(B22,P_italia_outubro_2026!$A$27:$A$33,0)),1) -> 6 | J22: 6 | K22: =J22 -> 6 | L22: =IF(H22="econômico",I22,IF(H22="upgrade",K22,J22)) -> 6 | M22: =E22*IF(OR(F22="pessoa",F22="pessoa-noite"),P_italia_outubro_2026!$B$8,1) -> 2 | N22: =IFERROR(INDEX(P_italia_outubro_2026!$B$22:$B$22,MATCH(G22,P_italia_outubro_2026!$A$22:$A$22,0)),1)*(1+IF(G22=P_italia_outubro_2026!$B$9,0,P_italia_outubro_2026!$B$14)) -> 1 | O22: =M22*I22*N22 -> 12 | P22: =M22*J22*N22 -> 12 | Q22: =M22*K22*N22 -> 12 | R22: =M22*L22*N22 -> 12 | S22: =IFERROR(INDEX(P_italia_outubro_2026!$D$27:$D$33,MATCH(B22,P_italia_outubro_2026!$A$27:$A$33,0)),"não") -> sim | T22: 8 | V22: — (preço plano × fator da categoria) | W22: — (sem upgrade pesquisado)
A23: est:alimentacao | B23: alimentacao | C23: Ajuste — Alimentação (itens somam mais que o previsto) | E23: 1 | F23: total | G23: EUR | H23: plano | I23: =J23*IFERROR(INDEX(P_italia_outubro_2026!$C$27:$C$33,MATCH(B23,P_italia_outubro_2026!$A$27:$A$33,0)),1) -> -64 | J23: -64 | K23: =J23 -> -64 | L23: =IF(H23="econômico",I23,IF(H23="upgrade",K23,J23)) -> -64 | M23: =E23*IF(OR(F23="pessoa",F23="pessoa-noite"),P_italia_outubro_2026!$B$8,1) -> 1 | N23: =IFERROR(INDEX(P_italia_outubro_2026!$B$22:$B$22,MATCH(G23,P_italia_outubro_2026!$A$22:$A$22,0)),1)*(1+IF(G23=P_italia_outubro_2026!$B$9,0,P_italia_outubro_2026!$B$14)) -> 1 | O23: =M23*I23*N23 -> -64 | P23: =M23*J23*N23 -> -64 | Q23: =M23*K23*N23 -> -64 | R23: =M23*L23*N23 -> -64 | S23: =IFERROR(INDEX(P_italia_outubro_2026!$D$27:$D$33,MATCH(B23,P_italia_outubro_2026!$A$27:$A$33,0)),"não") -> sim | X23: €65 por dia para o casal: bar de manhã, mercado ao meio-dia, trattoria à noite. Comer bem é o motivo da viagem — não corta.
A24: est:transporte-local | B24: transporte-local | C24: Estimativa restante — Transporte local | E24: 1 | F24: total | G24: EUR | H24: plano | I24: =J24*IFERROR(INDEX(P_italia_outubro_2026!$C$27:$C$33,MATCH(B24,P_italia_outubro_2026!$A$27:$A$33,0)),1) -> 4.7622 | J24: 6 | K24: =J24 -> 6 | L24: =IF(H24="econômico",I24,IF(H24="upgrade",K24,J24)) -> 6 | M24: =E24*IF(OR(F24="pessoa",F24="pessoa-noite"),P_italia_outubro_2026!$B$8,1) -> 1 | N24: =IFERROR(INDEX(P_italia_outubro_2026!$B$22:$B$22,MATCH(G24,P_italia_outubro_2026!$A$22:$A$22,0)),1)*(1+IF(G24=P_italia_outubro_2026!$B$9,0,P_italia_outubro_2026!$B$14)) -> 1 | O24: =M24*I24*N24 -> 4.7622 | P24: =M24*J24*N24 -> 6 | Q24: =M24*K24*N24 -> 6 | R24: =M24*L24*N24 -> 6 | S24: =IFERROR(INDEX(P_italia_outubro_2026!$D$27:$D$33,MATCH(B24,P_italia_outubro_2026!$A$27:$A$33,0)),"não") -> não | X24: FL1 do aeroporto, ATAC, Roma→Florença antecipado, Florença→Pisa. Econômico: Italo Low Cost.
A25: transp:atac | B25: transporte-local | C25: Bilhetes ATAC (metrô/ônibus de Roma), ≈ 10 viagens | E25: 1 | F25: pessoa | G25: EUR | H25: plano | I25: =J25*IFERROR(INDEX(P_italia_outubro_2026!$C$27:$C$33,MATCH(B25,P_italia_outubro_2026!$A$27:$A$33,0)),1) -> 11.9055 | J25: 15 | K25: =J25 -> 15 | L25: =IF(H25="econômico",I25,IF(H25="upgrade",K25,J25)) -> 15 | M25: =E25*IF(OR(F25="pessoa",F25="pessoa-noite"),P_italia_outubro_2026!$B$8,1) -> 2 | N25: =IFERROR(INDEX(P_italia_outubro_2026!$B$22:$B$22,MATCH(G25,P_italia_outubro_2026!$A$22:$A$22,0)),1)*(1+IF(G25=P_italia_outubro_2026!$B$9,0,P_italia_outubro_2026!$B$14)) -> 1 | O25: =M25*I25*N25 -> 23.811 | P25: =M25*J25*N25 -> 30 | Q25: =M25*K25*N25 -> 30 | R25: =M25*L25*N25 -> 30 | S25: =IFERROR(INDEX(P_italia_outubro_2026!$D$27:$D$33,MATCH(B25,P_italia_outubro_2026!$A$27:$A$33,0)),"não") -> não | V25: — (preço plano × fator da categoria) | W25: — (sem upgrade pesquisado) | X25: Roma se faz a pé; o metrô é para Vaticano e Testaccio. Pague por aproximação do cartão na catraca, sem comprar bilhete.
A26: transp:fl1 | B26: transporte-local | C26: Fiumicino → Roma: trem regional FL1 até Trastevere/Ostiense + metrô | E26: 1 | F26: pessoa | G26: EUR | H26: plano | I26: =J26*IFERROR(INDEX(P_italia_outubro_2026!$C$27:$C$33,MATCH(B26,P_italia_outubro_2026!$A$27:$A$33,0)),1) -> 6.3496 | J26: 8 | K26: =J26 -> 8 | L26: =IF(H26="econômico",I26,IF(H26="upgrade",K26,J26)) -> 8 | M26: =E26*IF(OR(F26="pessoa",F26="pessoa-noite"),P_italia_outubro_2026!$B$8,1) -> 2 | N26: =IFERROR(INDEX(P_italia_outubro_2026!$B$22:$B$22,MATCH(G26,P_italia_outubro_2026!$A$22:$A$22,0)),1)*(1+IF(G26=P_italia_outubro_2026!$B$9,0,P_italia_outubro_2026!$B$14)) -> 1 | O26: =M26*I26*N26 -> 12.6992 | P26: =M26*J26*N26 -> 16 | Q26: =M26*K26*N26 -> 16 | R26: =M26*L26*N26 -> 16 | S26: =IFERROR(INDEX(P_italia_outubro_2026!$D$27:$D$33,MATCH(B26,P_italia_outubro_2026!$A$27:$A$33,0)),"não") -> não | V26: — (preço plano × fator da categoria) | W26: — (sem upgrade pesquisado) | X26: O Leonardo Express (€14) só compensa se for direto a Termini. Para Monti, FL1 + metrô B leva o mesmo tempo por metade.
A27: transp:frecciarossa | B27: transporte-local | C27: Roma → Florença, Italo ou Frecciarossa | E27: 1 | F27: pessoa | G27: EUR | H27: plano | I27: =J27*IFERROR(INDEX(P_italia_outubro_2026!$C$27:$C$33,MATCH(B27,P_italia_outubro_2026!$A$27:$A$33,0)),1) -> 19.8425 | J27: 25 | K27: =J27 -> 25 | L27: =IF(H27="econômico",I27,IF(H27="upgrade",K27,J27)) -> 25 | M27: =E27*IF(OR(F27="pessoa",F27="pessoa-noite"),P_italia_outubro_2026!$B$8,1) -> 2 | N27: =IFERROR(INDEX(P_italia_outubro_2026!$B$22:$B$22,MATCH(G27,P_italia_outubro_2026!$A$22:$A$22,0)),1)*(1+IF(G27=P_italia_outubro_2026!$B$9,0,P_italia_outubro_2026!$B$14)) -> 1 | O27: =M27*I27*N27 -> 39.685 | P27: =M27*J27*N27 -> 50 | Q27: =M27*K27*N27 -> 50 | R27: =M27*L27*N27 -> 50 | S27: =IFERROR(INDEX(P_italia_outubro_2026!$D$27:$D$33,MATCH(B27,P_italia_outubro_2026!$A$27:$A$33,0)),"não") -> não | V27: — (preço plano × fator da categoria) | W27: — (sem upgrade pesquisado) | X27: 1h30. Comprar agora no site da operadora; Termini → SMN, as duas centrais.
A28: transp:pisa | B28: transporte-local | C28: Florença SMN → Pisa Aeroporto (regional + PisaMover) | E28: 1 | F28: pessoa | G28: EUR | H28: plano | I28: =J28*IFERROR(INDEX(P_italia_outubro_2026!$C$27:$C$33,MATCH(B28,P_italia_outubro_2026!$A$27:$A$33,0)),1) -> 9.5244 | J28: 12 | K28: =J28 -> 12 | L28: =IF(H28="econômico",I28,IF(H28="upgrade",K28,J28)) -> 12 | M28: =E28*IF(OR(F28="pessoa",F28="pessoa-noite"),P_italia_outubro_2026!$B$8,1) -> 2 | N28: =IFERROR(INDEX(P_italia_outubro_2026!$B$22:$B$22,MATCH(G28,P_italia_outubro_2026!$A$22:$A$22,0)),1)*(1+IF(G28=P_italia_outubro_2026!$B$9,0,P_italia_outubro_2026!$B$14)) -> 1 | O28: =M28*I28*N28 -> 19.0488 | P28: =M28*J28*N28 -> 24 | Q28: =M28*K28*N28 -> 24 | R28: =M28*L28*N28 -> 24 | S28: =IFERROR(INDEX(P_italia_outubro_2026!$D$27:$D$33,MATCH(B28,P_italia_outubro_2026!$A$27:$A$33,0)),"não") -> não | V28: — (preço plano × fator da categoria) | W28: — (sem upgrade pesquisado) | X28: ≈ 1h15 no total. Sair de Florença 3h30 antes do voo.
A29: dia1:r3 | B29: atracoes | C29: Pantheon (entrada €5) e Piazza Navona | D29: 46312 | E29: 1 | F29: pessoa | G29: EUR | H29: plano | I29: =J29*IFERROR(INDEX(P_italia_outubro_2026!$C$27:$C$33,MATCH(B29,P_italia_outubro_2026!$A$27:$A$33,0)),1) -> 5 | J29: 5 | K29: =J29 -> 5 | L29: =IF(H29="econômico",I29,IF(H29="upgrade",K29,J29)) -> 5 | M29: =E29*IF(OR(F29="pessoa",F29="pessoa-noite"),P_italia_outubro_2026!$B$8,1) -> 2 | N29: =IFERROR(INDEX(P_italia_outubro_2026!$B$22:$B$22,MATCH(G29,P_italia_outubro_2026!$A$22:$A$22,0)),1)*(1+IF(G29=P_italia_outubro_2026!$B$9,0,P_italia_outubro_2026!$B$14)) -> 1 | O29: =M29*I29*N29 -> 10 | P29: =M29*J29*N29 -> 10 | Q29: =M29*K29*N29 -> 10 | R29: =M29*L29*N29 -> 10 | S29: =IFERROR(INDEX(P_italia_outubro_2026!$D$27:$D$33,MATCH(B29,P_italia_outubro_2026!$A$27:$A$33,0)),"não") -> sim | T29: 1 | V29: — (preço plano × fator da categoria) | W29: — (sem upgrade pesquisado) | X29: Às 16h30 a luz entra pelo óculo na diagonal; a fila é curta no fim da tarde.
A30: dia2:r6 | B30: atracoes | C30: Coliseu — entrada 8h30 | D30: 46313 | E30: 1 | F30: pessoa | G30: EUR | H30: plano | I30: =J30*IFERROR(INDEX(P_italia_outubro_2026!$C$27:$C$33,MATCH(B30,P_italia_outubro_2026!$A$27:$A$33,0)),1) -> 18 | J30: 18 | K30: =J30 -> 18 | L30: =IF(H30="econômico",I30,IF(H30="upgrade",K30,J30)) -> 18 | M30: =E30*IF(OR(F30="pessoa",F30="pessoa-noite"),P_italia_outubro_2026!$B$8,1) -> 2 | N30: =IFERROR(INDEX(P_italia_outubro_2026!$B$22:$B$22,MATCH(G30,P_italia_outubro_2026!$A$22:$A$22,0)),1)*(1+IF(G30=P_italia_outubro_2026!$B$9,0,P_italia_outubro_2026!$B$14)) -> 1 | O30: =M30*I30*N30 -> 36 | P30: =M30*J30*N30 -> 36 | Q30: =M30*K30*N30 -> 36 | R30: =M30*L30*N30 -> 36 | S30: =IFERROR(INDEX(P_italia_outubro_2026!$D$27:$D$33,MATCH(B30,P_italia_outubro_2026!$A$27:$A$33,0)),"não") -> sim | T30: 2 | U30: ticketing.colosseo.it | V30: — (preço plano × fator da categoria) | W30: — (sem upgrade pesquisado) | X30: O ingresso vale 24h e inclui Fórum e Palatino. Chegue 20 min antes; o nome no ingresso tem que bater com o passaporte.
A31: dia3:r12 | B31: atracoes | C31: Museus Vaticanos e Capela Sistina — entrada 8h | D31: 46314 | E31: 1 | F31: pessoa | G31: EUR | H31: plano | I31: =J31*IFERROR(INDEX(P_italia_outubro_2026!$C$27:$C$33,MATCH(B31,P_italia_outubro_2026!$A$27:$A$33,0)),1) -> 25 | J31: 25 | K31: =J31 -> 25 | L31: =IF(H31="econômico",I31,IF(H31="upgrade",K31,J31)) -> 25 | M31: =E31*IF(OR(F31="pessoa",F31="pessoa-noite"),P_italia_outubro_2026!$B$8,1) -> 2 | N31: =IFERROR(INDEX(P_italia_outubro_2026!$B$22:$B$22,MATCH(G31,P_italia_outubro_2026!$A$22:$A$22,0)),1)*(1+IF(G31=P_italia_outubro_2026!$B$9,0,P_italia_outubro_2026!$B$14)) -> 1 | O31: =M31*I31*N31 -> 50 | P31: =M31*J31*N31 -> 50 | Q31: =M31*K31*N31 -> 50 | R31: =M31*L31*N31 -> 50 | S31: =IFERROR(INDEX(P_italia_outubro_2026!$D$27:$D$33,MATCH(B31,P_italia_outubro_2026!$A$27:$A$33,0)),"não") -> sim | T31: 3 | U31: museivaticani.va | V31: — (preço plano × fator da categoria) | W31: — (sem upgrade pesquisado) | X31: Última entrada às 18h. Da Sistina, a porta dos grupos à direita dá direto na Basílica, sem refazer a fila de fora.
A32: dia6:f6 | B32: atracoes | C32: Galleria degli Uffizi — entrada 8h15 | D32: 46317 | E32: 1 | F32: pessoa | G32: EUR | H32: plano | I32: =J32*IFERROR(INDEX(P_italia_outubro_2026!$C$27:$C$33,MATCH(B32,P_italia_outubro_2026!$A$27:$A$33,0)),1) -> 29 | J32: 29 | K32: =J32 -> 29 | L32: =IF(H32="econômico",I32,IF(H32="upgrade",K32,J32)) -> 29 | M32: =E32*IF(OR(F32="pessoa",F32="pessoa-noite"),P_italia_outubro_2026!$B$8,1) -> 2 | N32: =IFERROR(INDEX(P_italia_outubro_2026!$B$22:$B$22,MATCH(G32,P_italia_outubro_2026!$A$22:$A$22,0)),1)*(1+IF(G32=P_italia_outubro_2026!$B$9,0,P_italia_outubro_2026!$B$14)) -> 1 | O32: =M32*I32*N32 -> 58 | P32: =M32*J32*N32 -> 58 | Q32: =M32*K32*N32 -> 58 | R32: =M32*L32*N32 -> 58 | S32: =IFERROR(INDEX(P_italia_outubro_2026!$D$27:$D$33,MATCH(B32,P_italia_outubro_2026!$A$27:$A$33,0)),"não") -> sim | T32: 6 | U32: uffizi.it | V32: — (preço plano × fator da categoria) | W32: — (sem upgrade pesquisado) | X32: Última entrada 17h30. Suba direto ao segundo andar (salas 10–14, Botticelli) e desça depois.
A33: dia7:f12 | B33: atracoes | C33: Galleria dell'Accademia — o David | D33: 46318 | E33: 1 | F33: pessoa | G33: EUR | H33: plano | I33: =J33*IFERROR(INDEX(P_italia_outubro_2026!$C$27:$C$33,MATCH(B33,P_italia_outubro_2026!$A$27:$A$33,0)),1) -> 20 | J33: 20 | K33: =J33 -> 20 | L33: =IF(H33="econômico",I33,IF(H33="upgrade",K33,J33)) -> 20 | M33: =E33*IF(OR(F33="pessoa",F33="pessoa-noite"),P_italia_outubro_2026!$B$8,1) -> 2 | N33: =IFERROR(INDEX(P_italia_outubro_2026!$B$22:$B$22,MATCH(G33,P_italia_outubro_2026!$A$22:$A$22,0)),1)*(1+IF(G33=P_italia_outubro_2026!$B$9,0,P_italia_outubro_2026!$B$14)) -> 1 | O33: =M33*I33*N33 -> 40 | P33: =M33*J33*N33 -> 40 | Q33: =M33*K33*N33 -> 40 | R33: =M33*L33*N33 -> 40 | S33: =IFERROR(INDEX(P_italia_outubro_2026!$D$27:$D$33,MATCH(B33,P_italia_outubro_2026!$A$27:$A$33,0)),"não") -> sim | T33: 7 | V33: — (preço plano × fator da categoria) | W33: — (sem upgrade pesquisado) | X33: Fecha segunda. A sala do David fica no fundo à esquerda; vá direto e depois volte aos Prisioneiros.
A34: est:extras | B34: extras | C34: Estimativa restante — Extras e compras | E34: 1 | F34: total | G34: EUR | H34: plano | I34: =J34*IFERROR(INDEX(P_italia_outubro_2026!$C$27:$C$33,MATCH(B34,P_italia_outubro_2026!$A$27:$A$33,0)),1) -> 60 | J34: 100 | K34: =J34 -> 100 | L34: =IF(H34="econômico",I34,IF(H34="upgrade",K34,J34)) -> 100 | M34: =E34*IF(OR(F34="pessoa",F34="pessoa-noite"),P_italia_outubro_2026!$B$8,1) -> 1 | N34: =IFERROR(INDEX(P_italia_outubro_2026!$B$22:$B$22,MATCH(G34,P_italia_outubro_2026!$A$22:$A$22,0)),1)*(1+IF(G34=P_italia_outubro_2026!$B$9,0,P_italia_outubro_2026!$B$14)) -> 1 | O34: =M34*I34*N34 -> 60 | P34: =M34*J34*N34 -> 100 | Q34: =M34*K34*N34 -> 100 | R34: =M34*L34*N34 -> 100 | S34: =IFERROR(INDEX(P_italia_outubro_2026!$D$27:$D$33,MATCH(B34,P_italia_outubro_2026!$A$27:$A$33,0)),"não") -> não | X34: Teto assumido — diga o seu. Pompeia, se entrar, são +€130 aqui.
C36: Como usar
C37: Opção ▼ (coluna H, fundo creme) escolhe o que entra no total: econômico, plano ou upgrade. É o único lugar que você precisa mexer para montar o seu cenário.
C38: As três colunas de preço são por unidade (por pessoa, por noite ou total, conforme a Unidade). Azul = pesquisado; preto = derivado do plano.
C39: Preço econômico sem número explícito = preço do plano × fator da categoria (aba Parâmetros). Preço upgrade sem número = igual ao plano.
C40: Reservar / comprar (coluna U) abre o site oficial ou o comparador. Compre pelo link; a taxa de serviço de agregador entra no último passo.
C41: Linhas em itálico são estimativas da categoria: ao detalhar um item novo, reduza a estimativa para não contar duas vezes.
...

Sheet S_paris_outubro_2026
A1: Paris & Disneyland — Outubro 2026
A2: 7 → 11 de outubro · casal · Louvre, Orsay, bouillons, e dois dias de Halloween na Disney.
A4: Período | B4: =P_paris_outubro_2026!B4 -> 46302 | C4: =P_paris_outubro_2026!B5 -> 46306
A5: Pessoas · noites · dias | B5: =P_paris_outubro_2026!B8 -> 2 | C5: =P_paris_outubro_2026!B6 -> 4 | D5: =P_paris_outubro_2026!B7 -> 5
A7: Categoria | B7: Tudo econômico | C7: Plano | D7: Escolhido ★ | E7: Tudo upgrade | F7: Real | G7: Real − Escolhido | H7: Intocável
A8: =P_paris_outubro_2026!B27 -> Voos | B8: =SUMIFS(I_paris_outubro_2026!$O:$O,I_paris_outubro_2026!$B:$B,P_paris_outubro_2026!$A$27) -> 160 | C8: =SUMIFS(I_paris_outubro_2026!$P:$P,I_paris_outubro_2026!$B:$B,P_paris_outubro_2026!$A$27) -> 200 | D8: =SUMIFS(I_paris_outubro_2026!$R:$R,I_paris_outubro_2026!$B:$B,P_paris_outubro_2026!$A$27) -> 200 | E8: =SUMIFS(I_paris_outubro_2026!$Q:$Q,I_paris_outubro_2026!$B:$B,P_paris_outubro_2026!$A$27) -> 328 | H8: =P_paris_outubro_2026!D27 -> não
A9: =P_paris_outubro_2026!B28 -> Hospedagem | B9: =SUMIFS(I_paris_outubro_2026!$O:$O,I_paris_outubro_2026!$B:$B,P_paris_outubro_2026!$A$28) -> 385 | C9: =SUMIFS(I_paris_outubro_2026!$P:$P,I_paris_outubro_2026!$B:$B,P_paris_outubro_2026!$A$28) -> 510 | D9: =SUMIFS(I_paris_outubro_2026!$R:$R,I_paris_outubro_2026!$B:$B,P_paris_outubro_2026!$A$28) -> 510 | E9: =SUMIFS(I_paris_outubro_2026!$Q:$Q,I_paris_outubro_2026!$B:$B,P_paris_outubro_2026!$A$28) -> 785 | H9: =P_paris_outubro_2026!D28 -> não
A10: =P_paris_outubro_2026!B29 -> Taxa de turismo | B10: =SUMIFS(I_paris_outubro_2026!$O:$O,I_paris_outubro_2026!$B:$B,P_paris_outubro_2026!$A$29) -> 23 | C10: =SUMIFS(I_paris_outubro_2026!$P:$P,I_paris_outubro_2026!$B:$B,P_paris_outubro_2026!$A$29) -> 23 | D10: =SUMIFS(I_paris_outubro_2026!$R:$R,I_paris_outubro_2026!$B:$B,P_paris_outubro_2026!$A$29) -> 23 | E10: =SUMIFS(I_paris_outubro_2026!$Q:$Q,I_paris_outubro_2026!$B:$B,P_paris_outubro_2026!$A$29) -> 23 | H10: =P_paris_outubro_2026!D29 -> não
A11: =P_paris_outubro_2026!B30 -> Alimentação | B11: =SUMIFS(I_paris_outubro_2026!$O:$O,I_paris_outubro_2026!$B:$B,P_paris_outubro_2026!$A$30) -> 262.8 | C11: =SUMIFS(I_paris_outubro_2026!$P:$P,I_paris_outubro_2026!$B:$B,P_paris_outubro_2026!$A$30) -> 380 | D11: =SUMIFS(I_paris_outubro_2026!$R:$R,I_paris_outubro_2026!$B:$B,P_paris_outubro_2026!$A$30) -> 380 | E11: =SUMIFS(I_paris_outubro_2026!$Q:$Q,I_paris_outubro_2026!$B:$B,P_paris_outubro_2026!$A$30) -> 606.4 | H11: =P_paris_outubro_2026!D30 -> sim
A12: =P_paris_outubro_2026!B31 -> Transporte local | B12: =SUMIFS(I_paris_outubro_2026!$O:$O,I_paris_outubro_2026!$B:$B,P_paris_outubro_2026!$A$31) -> 104.281 | C12: =SUMIFS(I_paris_outubro_2026!$P:$P,I_paris_outubro_2026!$B:$B,P_paris_outubro_2026!$A$31) -> 128 | D12: =SUMIFS(I_paris_outubro_2026!$R:$R,I_paris_outubro_2026!$B:$B,P_paris_outubro_2026!$A$31) -> 128 | E12: =SUMIFS(I_paris_outubro_2026!$Q:$Q,I_paris_outubro_2026!$B:$B,P_paris_outubro_2026!$A$31) -> 264 | H12: =P_paris_outubro_2026!D31 -> não
A13: =P_paris_outubro_2026!B32 -> Atrações | B13: =SUMIFS(I_paris_outubro_2026!$O:$O,I_paris_outubro_2026!$B:$B,P_paris_outubro_2026!$A$32) -> 413.4 | C13: =SUMIFS(I_paris_outubro_2026!$P:$P,I_paris_outubro_2026!$B:$B,P_paris_outubro_2026!$A$32) -> 465 | D13: =SUMIFS(I_paris_outubro_2026!$R:$R,I_paris_outubro_2026!$B:$B,P_paris_outubro_2026!$A$32) -> 465 | E13: =SUMIFS(I_paris_outubro_2026!$Q:$Q,I_paris_outubro_2026!$B:$B,P_paris_outubro_2026!$A$32) -> 691.8 | H13: =P_paris_outubro_2026!D32 -> sim
A14: =P_paris_outubro_2026!B33 -> Extras e compras | B14: =SUMIFS(I_paris_outubro_2026!$O:$O,I_paris_outubro_2026!$B:$B,P_paris_outubro_2026!$A$33) -> 40 | C14: =SUMIFS(I_paris_outubro_2026!$P:$P,I_paris_outubro_2026!$B:$B,P_paris_outubro_2026!$A$33) -> 80 | D14: =SUMIFS(I_paris_outubro_2026!$R:$R,I_paris_outubro_2026!$B:$B,P_paris_outubro_2026!$A$33) -> 80 | E14: =SUMIFS(I_paris_outubro_2026!$Q:$Q,I_paris_outubro_2026!$B:$B,P_paris_outubro_2026!$A$33) -> 80 | H14: =P_paris_outubro_2026!D33 -> não
A15: Total previsto | B15: =SUM(B8:B14) -> 1388.481 | C15: =SUM(C8:C14) -> 1786 | D15: =SUM(D8:D14) -> 1786 | E15: =SUM(E8:E14) -> 2778.2
A16: Reserva para imprevistos | B16: =B15*P_paris_outubro_2026!$B$13 -> 138.8481 | C16: =C15*P_paris_outubro_2026!$B$13 -> 178.6 | D16: =D15*P_paris_outubro_2026!$B$13 -> 178.6 | E16: =E15*P_paris_outubro_2026!$B$13 -> 277.82
A17: Total com reserva | B17: =B15+B16 -> 1527.3291 | C17: =C15+C16 -> 1964.6 | D17: =D15+D16 -> 1964.6 | E17: =E15+E16 -> 3056.02
A19: Por pessoa | B19: =B15/P_paris_outubro_2026!$B$8 -> 694.2405 | C19: =C15/P_paris_outubro_2026!$B$8 -> 893 | D19: =D15/P_paris_outubro_2026!$B$8 -> 893 | E19: =E15/P_paris_outubro_2026!$B$8 -> 1389.1
A20: Por dia (grupo) | B20: =B15/P_paris_outubro_2026!$B$7 -> 277.6962 | C20: =C15/P_paris_outubro_2026!$B$7 -> 357.2 | D20: =D15/P_paris_outubro_2026!$B$7 -> 357.2 | E20: =E15/P_paris_outubro_2026!$B$7 -> 555.64
A21: Por pessoa por dia | B21: =B15/P_paris_outubro_2026!$B$8/P_paris_outubro_2026!$B$7 -> 138.8481 | C21: =C15/P_paris_outubro_2026!$B$8/P_paris_outubro_2026!$B$7 -> 178.6 | D21: =D15/P_paris_outubro_2026!$B$8/P_paris_outubro_2026!$B$7 -> 178.6 | E21: =E15/P_paris_outubro_2026!$B$8/P_paris_outubro_2026!$B$7 -> 277.82
A22: Gasto em solo (sem voos) | B22: =B15-SUMIFS(I_paris_outubro_2026!$O:$O,I_paris_outubro_2026!$B:$B,"voos") -> 1228.481 | C22: =C15-SUMIFS(I_paris_outubro_2026!$P:$P,I_paris_outubro_2026!$B:$B,"voos") -> 1586 | D22: =D15-SUMIFS(I_paris_outubro_2026!$R:$R,I_paris_outubro_2026!$B:$B,"voos") -> 1586 | E22: =E15-SUMIFS(I_paris_outubro_2026!$Q:$Q,I_paris_outubro_2026!$B:$B,"voos") -> 2450.2
A23: Alimentação / gasto em solo | B23: =IF(B22=0,0,SUMIFS(I_paris_outubro_2026!$O:$O,I_paris_outubro_2026!$B:$B,"alimentacao")/B22) -> 0.21392272 | C23: =IF(C22=0,0,SUMIFS(I_paris_outubro_2026!$P:$P,I_paris_outubro_2026!$B:$B,"alimentacao")/C22) -> 0.23959647 | D23: =IF(D22=0,0,SUMIFS(I_paris_outubro_2026!$R:$R,I_paris_outubro_2026!$B:$B,"alimentacao")/D22) -> 0.23959647 | E23: =IF(E22=0,0,SUMIFS(I_paris_outubro_2026!$Q:$Q,I_paris_outubro_2026!$B:$B,"alimentacao")/E22) -> 0.24749 | H23: meta 15–20%
A25: Teto do grupo | B25: =P_paris_outubro_2026!$B$12 -> 2000 | C25: =P_paris_outubro_2026!$B$12 -> 2000 | D25: =P_paris_outubro_2026!$B$12 -> 2000 | E25: =P_paris_outubro_2026!$B$12 -> 2000
A26: Folga contra o teto | B26: =B25-B17 -> 472.6709 | C26: =C25-C17 -> 35.4 | D26: =D25-D17 -> 35.4 | E26: =E25-E17 -> -1056.02
A27: Uso do teto | B27: =IF(B25=0,0,B17/B25) -> 0.76366455 | C27: =IF(C25=0,0,C17/C25) -> 0.9823 | D27: =IF(D25=0,0,D17/D25) -> 0.9823 | E27: =IF(E25=0,0,E17/E25) -> 1.52801
A28: Veredito | B28: =IF(B26>=0,"cabe, sobram "&TEXT(B26,"#,##0")&" €","faltam "&TEXT(-B26,"#,##0")&" €") -> cabe, sobram 473 € | C28: =IF(C26>=0,"cabe, sobram "&TEXT(C26,"#,##0")&" €","faltam "&TEXT(-C26,"#,##0")&" €") -> cabe, sobram 35 € | D28: =IF(D26>=0,"cabe, sobram "&TEXT(D26,"#,##0")&" €","faltam "&TEXT(-D26,"#,##0")&" €") -> cabe, sobram 35 € | E28: =IF(E26>=0,"cabe, sobram "&TEXT(E26,"#,##0")&" €","faltam "&TEXT(-E26,"#,##0")&" €") -> faltam 1,056 €
A29: Itens em upgrade / econômico | D29: =COUNTIF(I_paris_outubro_2026!$H:$H,"upgrade")&" up · "&COUNTIF(I_paris_outubro_2026!$H:$H,"econômico")&" eco" -> 0 up · 0 eco
A31: Como ler
A32: Escolhido ★ é o seu cenário: soma a opção marcada em cada linha da aba Itens (coluna Opção ▼). Tudo econômico e Tudo upgrade são os dois extremos.
A33: Plano = o roteiro como foi pesquisado. Real soma o que você lançar na aba Real durante a viagem; Real − Escolhido mostra onde estourou.
A34: Linhas rosa são intocáveis: a razão de ser da viagem. Cortar ali é planejar outra viagem.
A35: Nada aqui é digitado: tudo vem de Itens, Parâmetros e Real. Para mudar um número, mude lá.

Sheet P_paris_outubro_2026
A1: Paris & Disneyland — Outubro 2026
A2: Premissas da viagem. Azul = entrada; amarelo = o que mais mexe no total.
A3: Slug | B3: paris-outubro-2026
A4: Início | B4: 46302
A5: Fim | B5: 46306
A6: Noites | B6: =B5-B4 -> 4 | E6: fórmula
A7: Dias de viagem | B7: =B5-B4+1 -> 5 | E7: fórmula
A8: Pessoas | B8: 2
A9: Moeda de casa | B9: EUR
A10: Teto informado | B10: 2000
A11: Teto é por | B11: total | E11: total | pessoa
A12: Teto do grupo | B12: =IF(B11="pessoa",B10*B8,B10) -> 2000 | E12: fórmula
A13: Reserva para imprevistos (%) | B13: 0.1 | E13: sobre o total escolhido
A14: Margem do cartão fora do euro | B14: 0 | E14: 0% num Revolut/Wise; 1–3% em banco tradicional
A15: Opção padrão dos itens | B15: plano | E15: a coluna Opção da aba Itens decide item a item
A16: Pesquisa de | B16: 46277
A17: Status | B17: planejando
A20: Câmbio (EUR por 1 unidade da moeda)
A21: Moeda | B21: EUR por 1 | C21: Data | E21: Fonte
A22: EUR | B22: 1 | C22: 46277 | E22: moeda de casa
A25: Categorias | E25: Fator econômico: preço que sobra na opção econômica quando o item não tem uma explícita (0,8 = corta 20%). Intocável força 1.
A26: ID | B26: Nome | C26: Fator econômico | D26: Intocável | E26: De onde veio o número
A27: voos | B27: Voos | C27: 0.8 | D27: não | E27: Porto ⇄ Orly na Transavia para 2, só bagagem de mão (≈ €100 pp comprando agora; média de outubro €114). Econômico: promoção a €80 pp. Beauvais não entra: o ônibus come a diferença.
A28: hospedagem | B28: Hospedagem | C28: 0.8627 | D28: não | E28: 3 noites no ibis Bastille Opéra (≈ €130) + 1 noite no B&B parceiro da Disney (≈ €120). Econômico: ibis a €110 e B&B a €90.
A29: taxa-turismo | B29: Taxa de turismo | C29: 1 | D29: não | E29: Paris €3,25 pp/noite × 3 + Magny-le-Hongre ≈ €1,50 × 1, para 2.
A30: alimentacao | B30: Alimentação | C30: 1 | D30: sim | E30: €35 pp nos dias de Paris (bouillon, padaria, mercado), €45 pp nos dias de Disney. Comer bem é o motivo — não corta.
A31: transporte-local | B31: Transporte local | C31: 0.8281 | D31: não | E31: Orly €14 × 2 trechos × 2 = €56, RER A Disney €2,55 × 2 × 2 = €10, ≈ 12 bilhetes de metrô × €2,55 × 2 = €62. Econômico: 8 bilhetes de metrô.
A32: atracoes | B32: Atrações | C32: 1 | D32: sim | E32: Disney 2 dias/2 parques ≈ €154 pp (faixa "low", por data), Louvre €22 (residente), Orsay €16, Orangerie €12,50, Sainte-Chapelle €13, Eiffel escada €14,80 — para 2. Econômico: Disney 1 dia/2 parques + 1 dia/1 parque.
A33: extras | B33: Extras e compras | C33: 0.5 | D33: não | E33: Teto assumido — a Disney puxa. Diga o seu.

Sheet I_paris_outubro_2026
A1: ID | B1: Categoria | C1: Item | D1: Quando | E1: Qtd | F1: Unidade | G1: Moeda | H1: Opção ▼ | I1: Preço econômico | J1: Preço plano | K1: Preço upgrade | L1: Preço escolhido | M1: × (pessoas/noites) | N1: Câmbio + margem | O1: Total econômico (EUR) | P1: Total plano (EUR) | Q1: Total upgrade (EUR) | R1: Total escolhido (EUR) | S1: Intocável | T1: Dia | U1: Reservar / comprar | V1: O que é o econômico | W1: O que é o upgrade | X1: Fonte / observação
